Workbook
Name team: konkurs2!#REF!
Name team: #REF!
Name team: wyniki!$AX$5:$BD$47

Sheet wyniki
C5: Grupa A | F5: Grupa B | K5: Grupa C | O5: Grupa D | S5: Grupa E | W5: Grupa F | AA5: Grupa G | AE5: Grupa H | AI5: Grupa I | AM5: Grupa J | AQ5: Grupa K | AU5: Grupa L | AX5: druzyna | AY5: 1/16 | AZ5: 1/8 | BA5: 1/4 | BB5: 1/2 | BC5: fin | BD5: MW
B7: 1 | C7: Meksyk | G7: Kanada | K7: Brazylia | O7: Turcja | S7: Niemcy | W7: Holandia | AA7: Belgia | AE7: Hiszpania | AI7: Francja | AM7: Argentyna | AQ7: Portugalia | AU7: Anglia | AX7: Algieria
B8: 2 | C8: Korea Płd. | G8: Szwajcaria | K8: Maroko | O8: USA | S8: Wybrzeże Kości Sł. | W8: Szwecja | AA8: Egipt | AE8: Urugwaj | AI8: Norwegia | AM8: Algieria | AQ8: Kolumbia | AU8: Ghana | AX8: Anglia
B9: 3 | C9: Czechy | G9: Bośnia i Hercegowina | K9: Szkocja | O9: Paragwaj | S9: Ekwador | W9: Japonia | AA9: Iran | AE9: Arabia Saudyjska | AI9: Senegal | AM9: Austria | AQ9: DR Kongo | AU9: Chorwacja | AX9: Arabia Saudyjska
B10: 4 | C10: RPA | G10: Qatar | K10: Haiti | O10: Australia | S10: Curacao | W10: Tunezja | AA10: Nowa Zelandia | AE10: Rep. Ziel. Przylądka | AI10: Irak | AM10: Jordania | AQ10: Uzbekistan | AU10: Panama | AX10: Argentyna
AX11: Australia
AX12: Austria
Q13: 1/16 FINAŁU | AX13: Belgia
AX14: Bośnia i Hercegowina
E15: : | M15: : | U15: : | AC15: : | AM15: drużyny z 3go miejsca | AX15: Brazylia
AL16: A | AX16: Chorwacja
E17: : | M17: : | U17: : | AC17: : | AL17: B | AX17: Curacao
AL18: C | AX18: Czechy
E19: : | M19: : | U19: : | AC19: : | AL19: D | AX19: DR Kongo
AL20: E | AX20: Egipt
E21: : | M21: : | U21: : | AC21: : | AL21: F | AX21: Ekwador
AL22: G | AX22: Francja
Q23: 1/8 FINAŁU | AL23: H | AX23: Ghana
AL24: I | AX24: Haiti
M25: : | U25: : | AL25: J | AX25: Hiszpania
AL26: K | AX26: Holandia
M27: : | U27: : | AL27: L | AX27: Irak
AX28: Iran
M29: : | U29: : | AX29: Japonia
AX30: Jordania
M31: : | U31: : | AX31: Kanada
AX32: Kolumbia
Q33: ĆWIERĆFINAŁY | AX33: Korea Płd.
AX34: Maroko
M35: : | U35: : | AX35: Meksyk
AX36: Niemcy
M37: : | U37: : | AX37: Norwegia
AX38: Nowa Zelandia
Q39: PÓŁFINAŁY | AX39: Panama
AX40: Paragwaj
M41: : | U41: : | AX41: Portugalia
AX42: Qatar
Q43: FINAŁ | AX43: Rep. Ziel. Przylądka
AX44: RPA
Q45: : | AX45: Senegal
...

Sheet konkurs2
C2: wstaw swoje imię | G2: Punktów Ogółem | H2: =H72 -> #N/A
C4: 1. Faza grupowa: w żółtych polach, przy kazdym z krajów wstaw cyfry od 1-4 ustalając kolejność w grupach.
C5: Grupa A | F5: Grupa B | K5: Grupa C | O5: Grupa D | S5: Grupa E | W5: Grupa F | AA5: Grupa G | AE5: Grupa H | AI5: Grupa I | AM5: Grupa J | AQ5: Grupa K | AU5: Grupa L
C6: Meksyk | G6: Kanada | K6: Brazylia | O6: Turcja | S6: Niemcy | W6: Holandia | AA6: Belgia | AE6: Hiszpania | AI6: Francja | AM6: Argentyna | AQ6: Portugalia | AU6: Anglia | AX6: ABCD | AY6: =konkurs2!$S$16 | AZ6: =konkurs2!$AM$16 | BA6: =konkurs2!$AI$16 | BB6: =konkurs2!$W$16 | BC6: =konkurs2!$AE$16 | BD6: =konkurs2!$AA$16 | BE6: =konkurs2!$AU$16 | BF6: =konkurs2!$AQ$16 | BG6: =konkurs2!$C$16 | BH6: =konkurs2!$G$16 | BI6: =konkurs2!$K$16 | BJ6: =konkurs2!$O$16
C7: Korea Płd. | G7: Szwajcaria | K7: Maroko | O7: USA | S7: Wybrzeże Kości Sł. | W7: Szwecja | AA7: Egipt | AE7: Urugwaj | AI7: Norwegia | AM7: Algieria | AQ7: Kolumbia | AU7: Ghana | AX7: ABCE | AY7: =konkurs2!$AE$16 | AZ7: =konkurs2!$AA$16 | BA7: =konkurs2!$AI$16 | BB7: =konkurs2!$O$16 | BC7: =konkurs2!$AM$16 | BD7: =konkurs2!$W$16 | BE7: =konkurs2!$AU$16 | BF7: =konkurs2!$AQ$16 | BG7: =konkurs2!$C$16 | BH7: =konkurs2!$G$16 | BI7: =konkurs2!$K$16 | BJ7: =konkurs2!$S$16
C8: Czechy | G8: Bośnia i Hercegowina | K8: Szkocja | O8: Paragwaj | S8: Ekwador | W8: Japonia | AA8: Iran | AE8: Arabia Saudyjska | AI8: Senegal | AM8: Austria | AQ8: DR Kongo | AU8: Chorwacja | AX8: ABCF | AY8: =konkurs2!$S$16 | AZ8: =konkurs2!$AM$16 | BA8: =konkurs2!$AI$16 | BB8: =konkurs2!$O$16 | BC8: =konkurs2!$AE$16 | BD8: =konkurs2!$AA$16 | BE8: =konkurs2!$AU$16 | BF8: =konkurs2!$AQ$16 | BG8: =konkurs2!$C$16 | BH8: =konkurs2!$G$16 | BI8: =konkurs2!$K$16 | BJ8: =konkurs2!$W$16
C9: RPA | G9: Qatar | K9: Haiti | O9: Australia | S9: Curacao | W9: Tunezja | AA9: Nowa Zelandia | AE9: Rep. Ziel. Przylądka | AI9: Irak | AM9: Jordania | AQ9: Uzbekistan | AU9: Panama | AX9: ABCG | AY9: =konkurs2!$S$16 | AZ9: =konkurs2!$AM$16 | BA9: =konkurs2!$AI$16 | BB9: =konkurs2!$O$16 | BC9: =konkurs2!$AE$16 | BD9: =konkurs2!$W$16 | BE9: =konkurs2!$AU$16 | BF9: =konkurs2!$AQ$16 | BG9: =konkurs2!$C$16 | BH9: =konkurs2!$G$16 | BI9: =konkurs2!$K$16 | BJ9: =konkurs2!$AA$16
AX10: ABCH | AY10: =konkurs2!$S$16 | AZ10: =konkurs2!$AA$16 | BA10: =konkurs2!$AI$16 | BB10: =konkurs2!$O$16 | BC10: =konkurs2!$AM$16 | BD10: =konkurs2!$W$16 | BE10: =konkurs2!$AU$16 | BF10: =konkurs2!$AQ$16 | BG10: =konkurs2!$C$16 | BH10: =konkurs2!$G$16 | BI10: =konkurs2!$K$16 | BJ10: =konkurs2!$AE$16
C11: TWOJE TYPY: | AX11: ABCI | AY11: =konkurs2!$S$16 | AZ11: =konkurs2!$AA$16 | BA11: =konkurs2!$AM$16 | BB11: =konkurs2!$O$16 | BC11: =konkurs2!$AE$16 | BD11: =konkurs2!$W$16 | BE11: =konkurs2!$AU$16 | BF11: =konkurs2!$AQ$16 | BG11: =konkurs2!$C$16 | BH11: =konkurs2!$G$16 | BI11: =konkurs2!$K$16 | BJ11: =konkurs2!$AI$16
AX12: ABCJ | AY12: =konkurs2!$S$16 | AZ12: =konkurs2!$AA$16 | BA12: =konkurs2!$AI$16 | BB12: =konkurs2!$O$16 | BC12: =konkurs2!$AE$16 | BD12: =konkurs2!$W$16 | BE12: =konkurs2!$AU$16 | BF12: =konkurs2!$AQ$16 | BG12: =konkurs2!$C$16 | BH12: =konkurs2!$G$16 | BI12: =konkurs2!$K$16 | BJ12: =konkurs2!$AM$16
C13: A | D13: pkt | G13: B | H13: pkt | K13: C | L13: pkt | O13: D | P13: pkt | S13: E | T13: pkt | W13: F | X13: pkt | AA13: G | AB13: pkt | AE13: H | AF13: pkt | AI13: I | AJ13: pkt | AM13: J | AN13: pkt | AQ13: K | AR13: pkt | AU13: L | AV13: pkt | AX13: ABCK | AY13: =konkurs2!$S$16 | AZ13: =konkurs2!$AA$16 | BA13: =konkurs2!$AM$16 | BB13: =konkurs2!$O$16 | BC13: =konkurs2!$AE$16 | BD13: =konkurs2!$W$16 | BE13: =konkurs2!$AU$16 | BF13: =konkurs2!$AI$16 | BG13: =konkurs2!$C$16 | BH13: =konkurs2!$G$16 | BI13: =konkurs2!$K$16 | BJ13: =konkurs2!$AQ$16
C14: =IF(C6="","",VLOOKUP(1,B6:C9,2,FALSE)) -> #N/A | D14: =IF(wyniki!C7=konkurs2!C14,1,0) -> #N/A | G14: =IF(G6="","",VLOOKUP(1,F6:G9,2,FALSE)) -> #N/A | H14: =IF(wyniki!G7=konkurs2!G14,1,0) -> #N/A | K14: =IF(K6="","",VLOOKUP(1,J6:K9,2,FALSE)) -> #N/A | L14: =IF(wyniki!K7=konkurs2!K14,1,0) -> #N/A | O14: =IF(O6="","",VLOOKUP(1,N6:O9,2,FALSE)) -> #N/A | P14: =IF(wyniki!O7=konkurs2!O14,1,0) -> #N/A | S14: =IF(S6="","",VLOOKUP(1,R6:S9,2,FALSE)) -> #N/A | T14: =IF(wyniki!S7=konkurs2!S14,1,0) -> #N/A | W14: =IF(W6="","",VLOOKUP(1,V6:W9,2,FALSE)) -> #N/A | X14: =IF(wyniki!W7=konkurs2!W14,1,0) -> #N/A | AA14: =IF(AA6="","",VLOOKUP(1,Z6:AA9,2,FALSE)) -> #N/A | AB14: =IF(wyniki!AA7=konkurs2!AA14,1,0) -> #N/A | AE14: =IF(AE6="","",VLOOKUP(1,AD6:AE9,2,FALSE)) -> #N/A | AF14: =IF(wyniki!AE7=konkurs2!AE14,1,0) -> #N/A | AI14: =IF(AI6="","",VLOOKUP(1,AH6:AI9,2,FALSE)) -> #N/A | AJ14: =IF(wyniki!AI7=konkurs2!AI14,1,0) -> #N/A | AM14: =IF(AM6="","",VLOOKUP(1,AL6:AM9,2,FALSE)) -> #N/A | AN14: =IF(wyniki!AM7=konkurs2!AM14,1,0) -> #N/A | AQ14: =IF(AQ6="","",VLOOKUP(1,AP6:AQ9,2,FALSE)) -> #N/A | AR14: =IF(wyniki!AQ7=konkurs2!AQ14,1,0) -> #N/A | AU14: =IF(AU6="","",VLOOKUP(1,AT6:AU9,2,FALSE)) -> #N/A | AV14: =IF(wyniki!AU7=konkurs2!AU14,1,0) -> #N/A | AX14: ABCL | AY14: =konkurs2!$S$16 | AZ14: =konkurs2!$AA$16 | BA14: =konkurs2!$AM$16 | BB14: =konkurs2!$O$16 | BC14: =konkurs2!$AE$16 | BD14: =konkurs2!$W$16 | BE14: =konkurs2!$AI$16 | BF14: =konkurs2!$AQ$16 | BG14: =konkurs2!$C$16 | BH14: =konkurs2!$G$16 | BI14: =konkurs2!$K$16 | BJ14: =konkurs2!$AU$16
C15: =IF(B6="","",VLOOKUP(2,B6:C9,2,FALSE)) | D15: =IF(wyniki!C8=konkurs2!C15,1,0) -> 0 | G15: =IF(F6="","",VLOOKUP(2,F6:G9,2,FALSE)) | H15: =IF(wyniki!G8=konkurs2!G15,1,0) -> 0 | K15: =IF(J6="","",VLOOKUP(2,J6:K9,2,FALSE)) | L15: =IF(wyniki!K8=konkurs2!K15,1,0) -> 0 | O15: =IF(N6="","",VLOOKUP(2,N6:O9,2,FALSE)) | P15: =IF(wyniki!O8=konkurs2!O15,1,0) -> 0 | S15: =IF(R6="","",VLOOKUP(2,R6:S9,2,FALSE)) | T15: =IF(wyniki!S8=konkurs2!S15,1,0) -> 0 | W15: =IF(V6="","",VLOOKUP(2,V6:W9,2,FALSE)) | X15: =IF(wyniki!W8=konkurs2!W15,1,0) -> 0 | AA15: =IF(Z6="","",VLOOKUP(2,Z6:AA9,2,FALSE)) | AB15: =IF(wyniki!AA8=konkurs2!AA15,1,0) -> 0 | AE15: =IF(AD6="","",VLOOKUP(2,AD6:AE9,2,FALSE)) | AF15: =IF(wyniki!AE8=konkurs2!AE15,1,0) -> 0 | AI15: =IF(AH6="","",VLOOKUP(2,AH6:AI9,2,FALSE)) | AJ15: =IF(wyniki!AI8=konkurs2!AI15,1,0) -> 0 | AM15: =IF(AL6="","",VLOOKUP(2,AL6:AM9,2,FALSE)) | AN15: =IF(wyniki!AM8=konkurs2!AM15,1,0) -> 0 | AQ15: =IF(AP6="","",VLOOKUP(2,AP6:AQ9,2,FALSE)) | AR15: =IF(wyniki!AQ8=konkurs2!AQ15,1,0) -> 0 | AU15: =IF(AT6="","",VLOOKUP(2,AT6:AU9,2,FALSE)) | AV15: =IF(wyniki!AU8=konkurs2!AU15,1,0) -> 0 | AX15: ABDE | AY15: =konkurs2!$AE$16 | AZ15: =konkurs2!$AA$16 | BA15: =konkurs2!$AI$16 | BB15: =konkurs2!$K$16 | BC15: =konkurs2!$AM$16 | BD15: =konkurs2!$W$16 | BE15: =konkurs2!$AU$16 | BF15: =konkurs2!$AQ$16 | BG15: =konkurs2!$C$16 | BH15: =konkurs2!$G$16 | BI15: =konkurs2!$O$16 | BJ15: =konkurs2!$S$16
C16: =IF(B7="","",VLOOKUP(3,B6:C9,2,FALSE)) | D16: =IF(wyniki!C9=konkurs2!C16,1,0) -> 0 | G16: =IF(F7="","",VLOOKUP(3,F6:G9,2,FALSE)) | H16: =IF(wyniki!G9=konkurs2!G16,1,0) -> 0 | K16: =IF(J7="","",VLOOKUP(3,J6:K9,2,FALSE)) | L16: =IF(wyniki!K9=konkurs2!K16,1,0) -> 0 | O16: =IF(N7="","",VLOOKUP(3,N6:O9,2,FALSE)) | P16: =IF(wyniki!O9=konkurs2!O16,1,0) -> 0 | S16: =IF(R7="","",VLOOKUP(3,R6:S9,2,FALSE)) | T16: =IF(wyniki!S9=konkurs2!S16,1,0) -> 0 | W16: =IF(V7="","",VLOOKUP(3,V6:W9,2,FALSE)) | X16: =IF(wyniki!W9=konkurs2!W16,1,0) -> 0 | AA16: =IF(Z7="","",VLOOKUP(3,Z6:AA9,2,FALSE)) | AB16: =IF(wyniki!AA9=konkurs2!AA16,1,0) -> 0 | AE16: =IF(AD7="","",VLOOKUP(3,AD6:AE9,2,FALSE)) | AF16: =IF(wyniki!AE9=konkurs2!AE16,1,0) -> 0 | AI16: =IF(AH7="","",VLOOKUP(3,AH6:AI9,2,FALSE)) | AJ16: =IF(wyniki!AI9=konkurs2!AI16,1,0) -> 0 | AM16: =IF(AL7="","",VLOOKUP(3,AL6:AM9,2,FALSE)) | AN16: =IF(wyniki!AM9=konkurs2!AM16,1,0) -> 0 | AQ16: =IF(AP7="","",VLOOKUP(3,AP6:AQ9,2,FALSE)) | AR16: =IF(wyniki!AQ9=konkurs2!AQ16,1,0) -> 0 | AU16: =IF(AT7="","",VLOOKUP(3,AT6:AU9,2,FALSE)) | AV16: =IF(wyniki!AU9=konkurs2!AU16,1,0) -> 0 | AX16: ABDF | AY16: =konkurs2!$S$16 | AZ16: =konkurs2!$AM$16 | BA16: =konkurs2!$AI$16 | BB16: =konkurs2!$K$16 | BC16: =konkurs2!$AE$16 | BD16: =konkurs2!$AA$16 | BE16: =konkurs2!$AU$16 | BF16: =konkurs2!$AQ$16 | BG16: =konkurs2!$C$16 | BH16: =konkurs2!$G$16 | BI16: =konkurs2!$O$16 | BJ16: =konkurs2!$W$16
C17: =IF(B8="","",VLOOKUP(4,B6:C9,2,FALSE)) | D17: =IF(wyniki!C10=konkurs2!C17,1,0) -> 0 | G17: =IF(F8="","",VLOOKUP(4,F6:G9,2,FALSE)) | H17: =IF(wyniki!G10=konkurs2!G17,1,0) -> 0 | K17: =IF(J8="","",VLOOKUP(4,J6:K9,2,FALSE)) | L17: =IF(wyniki!K10=konkurs2!K17,1,0) -> 0 | O17: =IF(N8="","",VLOOKUP(4,N6:O9,2,FALSE)) | P17: =IF(wyniki!O10=konkurs2!O17,1,0) -> 0 | S17: =IF(R8="","",VLOOKUP(4,R6:S9,2,FALSE)) | T17: =IF(wyniki!S10=konkurs2!S17,1,0) -> 0 | W17: =IF(V8="","",VLOOKUP(4,V6:W9,2,FALSE)) | X17: =IF(wyniki!W10=konkurs2!W17,1,0) -> 0 | AA17: =IF(Z8="","",VLOOKUP(4,Z6:AA9,2,FALSE)) | AB17: =IF(wyniki!AA10=konkurs2!AA17,1,0) -> 0 | AE17: =IF(AD8="","",VLOOKUP(4,AD6:AE9,2,FALSE)) | AF17: =IF(wyniki!AE10=konkurs2!AE17,1,0) -> 0 | AI17: =IF(AH8="","",VLOOKUP(4,AH6:AI9,2,FALSE)) | AJ17: =IF(wyniki!AI10=konkurs2!AI17,1,0) -> 0 | AM17: =IF(AL8="","",VLOOKUP(4,AL6:AM9,2,FALSE)) | AN17: =IF(wyniki!AM10=konkurs2!AM17,1,0) -> 0 | AQ17: =IF(AP8="","",VLOOKUP(4,AP6:AQ9,2,FALSE)) | AR17: =IF(wyniki!AQ10=konkurs2!AQ17,1,0) -> 0 | AU17: =IF(AT8="","",VLOOKUP(4,AT6:AU9,2,FALSE)) | AV17: =IF(wyniki!AU10=konkurs2!AU17,1,0) -> 0 | AX17: ABDG | AY17: =konkurs2!$S$16 | AZ17: =konkurs2!$AM$16 | BA17: =konkurs2!$AI$16 | BB17: =konkurs2!$K$16 | BC17: =konkurs2!$AE$16 | BD17: =konkurs2!$W$16 | BE17: =konkurs2!$AU$16 | BF17: =konkurs2!$AQ$16 | BG17: =konkurs2!$C$16 | BH17: =konkurs2!$G$16 | BI17: =konkurs2!$O$16 | BJ17: =konkurs2!$AA$16
AX18: ABDH | AY18: =konkurs2!$S$16 | AZ18: =konkurs2!$AA$16 | BA18: =konkurs2!$AI$16 | BB18: =konkurs2!$K$16 | BC18: =konkurs2!$AM$16 | BD18: =konkurs2!$W$16 | BE18: =konkurs2!$AU$16 | BF18: =konkurs2!$AQ$16 | BG18: =konkurs2!$C$16 | BH18: =konkurs2!$G$16 | BI18: =konkurs2!$O$16 | BJ18: =konkurs2!$AE$16
G19: Punkty za faze grupowa | H19: =D14++D15+D16+D17+H14+H15+H16+H17+L14+L15+L16+L17+P14+P15+P16+P17+T14+T15+T16+T17+X14+X15+X16+X17+AB14+AB15+AB16+AB17+AF14+AF15+AF16+AF17+AJ14+AJ15+AJ16+AJ17+AN14+AN15+AN16+AN17+AR14+AR15+AR16+AR17+AV14+AV15+AV16+AV17 -> #N/A | AX19: ABDI | AY19: =konkurs2!$S$16 | AZ19: =konkurs2!$AA$16 | BA19: =konkurs2!$AM$16 | BB19: =konkurs2!$K$16 | BC19: =konkurs2!$AE$16 | BD19: =konkurs2!$W$16 | BE19: =konkurs2!$AU$16 | BF19: =konkurs2!$AQ$16 | BG19: =konkurs2!$C$16 | BH19: =konkurs2!$G$16 | BI19: =konkurs2!$O$16 | BJ19: =konkurs2!$AI$16
AX20: ABDJ | AY20: =konkurs2!$S$16 | AZ20: =konkurs2!$AA$16 | BA20: =konkurs2!$AI$16 | BB20: =konkurs2!$K$16 | BC20: =konkurs2!$AE$16 | BD20: =konkurs2!$W$16 | BE20: =konkurs2!$AU$16 | BF20: =konkurs2!$AQ$16 | BG20: =konkurs2!$C$16 | BH20: =konkurs2!$G$16 | BI20: =konkurs2!$O$16 | BJ20: =konkurs2!$AM$16
C21: Ustal, z których grup nie awansują cztery (4) zespoły z trzecich miejsc (zaznaczone u góry na pomarańczowo). Pozostałe 8 drużyn awansuje. | AX21: ABDK | AY21: =konkurs2!$S$16 | AZ21: =konkurs2!$AA$16 | BA21: =konkurs2!$AM$16 | BB21: =konkurs2!$K$16 | BC21: =konkurs2!$AE$16 | BD21: =konkurs2!$W$16 | BE21: =konkurs2!$AU$16 | BF21: =konkurs2!$AI$16 | BG21: =konkurs2!$C$16 | BH21: =konkurs2!$G$16 | BI21: =konkurs2!$O$16 | BJ21: =konkurs2!$AQ$16
C22: 2. Kliknij na granatowe pole "ABCD" i wybierz swój wariant z listy rozwijanej | AX22: ABDL | AY22: =konkurs2!$S$16 | AZ22: =konkurs2!$AA$16 | BA22: =konkurs2!$AM$16 | BB22: =konkurs2!$K$16 | BC22: =konkurs2!$AE$16 | BD22: =konkurs2!$W$16 | BE22: =konkurs2!$AI$16 | BF22: =konkurs2!$AQ$16 | BG22: =konkurs2!$C$16 | BH22: =konkurs2!$G$16 | BI22: =konkurs2!$O$16 | BJ22: =konkurs2!$AU$16
AX23: ABEF | AY23: =konkurs2!$AE$16 | AZ23: =konkurs2!$AA$16 | BA23: =konkurs2!$AI$16 | BB23: =konkurs2!$K$16 | BC23: =konkurs2!$AM$16 | BD23: =konkurs2!$O$16 | BE23: =konkurs2!$AU$16 | BF23: =konkurs2!$AQ$16 | BG23: =konkurs2!$C$16 | BH23: =konkurs2!$G$16 | BI23: =konkurs2!$S$16 | BJ23: =konkurs2!$W$16
G24: ABCK | AX24: ABEG | AY24: =konkurs2!$K$16 | AZ24: =konkurs2!$AM$16 | BA24: =konkurs2!$AI$16 | BB24: =konkurs2!$O$16 | BC24: =konkurs2!$AE$16 | BD24: =konkurs2!$W$16 | BE24: =konkurs2!$AU$16 | BF24: =konkurs2!$AQ$16 | BG24: =konkurs2!$C$16 | BH24: =konkurs2!$G$16 | BI24: =konkurs2!$S$16 | BJ24: =konkurs2!$AA$16
G25: odpadną 4 drużyny: | K25: awansuje 8 drużyn: | AX25: ABEH | AY25: =konkurs2!$K$16 | AZ25: =konkurs2!$AA$16 | BA25: =konkurs2!$AI$16 | BB25: =konkurs2!$O$16 | BC25: =konkurs2!$AM$16 | BD25: =konkurs2!$W$16 | BE25: =konkurs2!$AU$16 | BF25: =konkurs2!$AQ$16 | BG25: =konkurs2!$C$16 | BH25: =konkurs2!$G$16 | BI25: =konkurs2!$S$16 | BJ25: =konkurs2!$AE$16
G26: =LOOKUP(G24,AX6:AX500,BG6:BG500) | K26: =LOOKUP(G24,AX6:AX500,AY6:AY500) | AX26: ABEI | AY26: =konkurs2!$K$16 | AZ26: =konkurs2!$AA$16 | BA26: =konkurs2!$AM$16 | BB26: =konkurs2!$O$16 | BC26: =konkurs2!$AE$16 | BD26: =konkurs2!$W$16 | BE26: =konkurs2!$AU$16 | BF26: =konkurs2!$AQ$16 | BG26: =konkurs2!$C$16 | BH26: =konkurs2!$G$16 | BI26: =konkurs2!$S$16 | BJ26: =konkurs2!$AI$16
G27: =LOOKUP(G24,AX6:AX500,BH6:BH500) | K27: =LOOKUP(G24,AX6:AX500,AZ6:AZ500) | AX27: ABEJ | AY27: =konkurs2!$K$16 | AZ27: =konkurs2!$AA$16 | BA27: =konkurs2!$AI$16 | BB27: =konkurs2!$O$16 | BC27: =konkurs2!$AE$16 | BD27: =konkurs2!$W$16 | BE27: =konkurs2!$AU$16 | BF27: =konkurs2!$AQ$16 | BG27: =konkurs2!$C$16 | BH27: =konkurs2!$G$16 | BI27: =konkurs2!$S$16 | BJ27: =konkurs2!$AM$16
G28: =LOOKUP(G24,AX6:AX500,BI6:BI500) | K28: =LOOKUP(G24,AX6:AX500,BA6:BA500) | AX28: ABEK | AY28: =konkurs2!$K$16 | AZ28: =konkurs2!$AA$16 | BA28: =konkurs2!$AM$16 | BB28: =konkurs2!$O$16 | BC28: =konkurs2!$AE$16 | BD28: =konkurs2!$W$16 | BE28: =konkurs2!$AU$16 | BF28: =konkurs2!$AI$16 | BG28: =konkurs2!$C$16 | BH28: =konkurs2!$G$16 | BI28: =konkurs2!$S$16 | BJ28: =konkurs2!$AQ$16
G29: =LOOKUP(G24,AX6:AX500,BJ6:BJ500) | K29: =LOOKUP(G24,AX6:AX500,BB6:BB500) | AX29: ABEL | AY29: =konkurs2!$K$16 | AZ29: =konkurs2!$AA$16 | BA29: =konkurs2!$AM$16 | BB29: =konkurs2!$O$16 | BC29: =konkurs2!$AE$16 | BD29: =konkurs2!$W$16 | BE29: =konkurs2!$AI$16 | BF29: =konkurs2!$AQ$16 | BG29: =konkurs2!$C$16 | BH29: =konkurs2!$G$16 | BI29: =konkurs2!$S$16 | BJ29: =konkurs2!$AU$16
K30: =LOOKUP(G24,AX6:AX500,BC6:BC500) | AX30: ABFG | AY30: =konkurs2!$S$16 | AZ30: =konkurs2!$AM$16 | BA30: =konkurs2!$AI$16 | BB30: =konkurs2!$K$16 | BC30: =konkurs2!$AE$16 | BD30: =konkurs2!$O$16 | BE30: =konkurs2!$AU$16 | BF30: =konkurs2!$AQ$16 | BG30: =konkurs2!$C$16 | BH30: =konkurs2!$G$16 | BI30: =konkurs2!$W$16 | BJ30: =konkurs2!$AA$16
K31: =LOOKUP(G24,AX6:AX500,BD6:BD500) | AX31: ABFH | AY31: =konkurs2!$S$16 | AZ31: =konkurs2!$AA$16 | BA31: =konkurs2!$AI$16 | BB31: =konkurs2!$K$16 | BC31: =konkurs2!$AM$16 | BD31: =konkurs2!$O$16 | BE31: =konkurs2!$AU$16 | BF31: =konkurs2!$AQ$16 | BG31: =konkurs2!$C$16 | BH31: =konkurs2!$G$16 | BI31: =konkurs2!$W$16 | BJ31: =konkurs2!$AE$16
K32: =LOOKUP(G24,AX6:AX500,BE6:BE500) | AX32: ABFI | AY32: =konkurs2!$S$16 | AZ32: =konkurs2!$AA$16 | BA32: =konkurs2!$AM$16 | BB32: =konkurs2!$K$16 | BC32: =konkurs2!$AE$16 | BD32: =konkurs2!$O$16 | BE32: =konkurs2!$AU$16 | BF32: =konkurs2!$AQ$16 | BG32: =konkurs2!$C$16 | BH32: =konkurs2!$G$16 | BI32: =konkurs2!$W$16 | BJ32: =konkurs2!$AI$16
K33: =LOOKUP(G24,AX6:AX500,BF6:BF500) | AX33: ABFJ | AY33: =konkurs2!$S$16 | AZ33: =konkurs2!$AA$16 | BA33: =konkurs2!$AI$16 | BB33: =konkurs2!$K$16 | BC33: =konkurs2!$AE$16 | BD33: =konkurs2!$O$16 | BE33: =konkurs2!$AU$16 | BF33: =konkurs2!$AQ$16 | BG33: =konkurs2!$C$16 | BH33: =konkurs2!$G$16 | BI33: =konkurs2!$W$16 | BJ33: =konkurs2!$AM$16
AX34: ABFK | AY34: =konkurs2!$S$16 | AZ34: =konkurs2!$AA$16 | BA34: =konkurs2!$AM$16 | BB34: =konkurs2!$K$16 | BC34: =konkurs2!$AE$16 | BD34: =konkurs2!$O$16 | BE34: =konkurs2!$AU$16 | BF34: =konkurs2!$AI$16 | BG34: =konkurs2!$C$16 | BH34: =konkurs2!$G$16 | BI34: =konkurs2!$W$16 | BJ34: =konkurs2!$AQ$16
C35: 3. Runda pucharowa. Wstaw 1 lub 2 w żóltych polach ustalając drużynę która przechodzi do kolejnej rundy | AX35: ABFL | AY35: =konkurs2!$S$16 | AZ35: =konkurs2!$AA$16 | BA35: =konkurs2!$AM$16 | BB35: =konkurs2!$K$16 | BC35: =konkurs2!$AE$16 | BD35: =konkurs2!$O$16 | BE35: =konkurs2!$AI$16 | BF35: =konkurs2!$AQ$16 | BG35: =konkurs2!$C$16 | BH35: =konkurs2!$G$16 | BI35: =konkurs2!$W$16 | BJ35: =konkurs2!$AU$16
AX36: ABGH | AY36: =konkurs2!$K$16 | AZ36: =konkurs2!$AM$16 | BA36: =konkurs2!$S$16 | BB36: =konkurs2!$O$16 | BC36: =konkurs2!$AI$16 | BD36: =konkurs2!$W$16 | BE36: =konkurs2!$AU$16 | BF36: =konkurs2!$AQ$16 | BG36: =konkurs2!$C$16 | BH36: =konkurs2!$G$16 | BI36: =konkurs2!$AA$16 | BJ36: =konkurs2!$AE$16
G37: Punkty za fazę the last 32 | H37: =B39+B41+B43+B45+H39+H41+H43+H45+J39+J41+J43+J45+P39+P41+P43+P45+R39+R41+R43+R45+X39+X41+X43+X45+Z39+Z41+Z43+Z45+AF39+AF41+AF43+AF45 -> #N/A | P37: 1/16 FINAŁU | AX37: ABGI | AY37: =konkurs2!$K$16 | AZ37: =konkurs2!$AM$16 | BA37: =konkurs2!$S$16 | BB37: =konkurs2!$O$16 | BC37: =konkurs2!$AE$16 | BD37: =konkurs2!$W$16 | BE37: =konkurs2!$AU$16 | BF37: =konkurs2!$AQ$16 | BG37: =konkurs2!$C$16 | BH37: =konkurs2!$G$16 | BI37: =konkurs2!$AA$16 | BJ37: =konkurs2!$AI$16
B38: pkt | J38: pkt | Z38: pkt | AX38: ABGJ | AY38: =konkurs2!$K$16 | AZ38: =konkurs2!$S$16 | BA38: =konkurs2!$AI$16 | BB38: =konkurs2!$O$16 | BC38: =konkurs2!$AE$16 | BD38: =konkurs2!$W$16 | BE38: =konkurs2!$AU$16 | BF38: =konkurs2!$AQ$16 | BG38: =konkurs2!$C$16 | BH38: =konkurs2!$G$16 | BI38: =konkurs2!$AA$16 | BJ38: =konkurs2!$AM$16
B39: =LOOKUP(C39,wyniki!$AX$7:$AY$54) -> #N/A | C39: =S14 -> #N/A | F39: =K29 | H39: =LOOKUP(F39,wyniki!$AX$7:$AY$54) -> #N/A | J39: =LOOKUP(K39,wyniki!$AX$7:$AY$54) -> #N/A | K39: =AQ15 | N39: =AU15 | P39: =LOOKUP(N39,wyniki!$AX$7:$AY$54) -> #N/A | R39: =LOOKUP(S39,wyniki!$AX$7:$AY$54) -> #N/A | S39: =K14 -> #N/A | V39: =W15 | X39: =LOOKUP(V39,wyniki!$AX$7:$AY$54) -> #N/A | Z39: =LOOKUP(AA39,wyniki!$AX$7:$AY$54) -> #N/A | AA39: =AM14 -> #N/A | AD39: =AE15 | AF39: =LOOKUP(AD39,wyniki!$AX$7:$AY$54) -> #N/A | AX39: ABGK | AY39: =konkurs2!$K$16 | AZ39: =konkurs2!$AM$16 | BA39: =konkurs2!$S$16 | BB39: =konkurs2!$O$16 | BC39: =konkurs2!$AE$16 | BD39: =konkurs2!$W$16 | BE39: =konkurs2!$AU$16 | BF39: =konkurs2!$AI$16 | BG39: =konkurs2!$C$16 | BH39: =konkurs2!$G$16 | BI39: =konkurs2!$AA$16 | BJ39: =konkurs2!$AQ$16
AX40: ABGL | AY40: =konkurs2!$K$16 | AZ40: =konkurs2!$AM$16 | BA40: =konkurs2!$S$16 | BB40: =konkurs2!$O$16 | BC40: =konkurs2!$AE$16 | BD40: =konkurs2!$W$16 | BE40: =konkurs2!$AI$16 | BF40: =konkurs2!$AQ$16 | BG40: =konkurs2!$C$16 | BH40: =konkurs2!$G$16 | BI40: =konkurs2!$AA$16 | BJ40: =konkurs2!$AU$16
B41: =LOOKUP(C41,wyniki!$AX$7:$AY$54) -> #N/A | C41: =AI14 -> #N/A | F41: =K31 | H41: =LOOKUP(F41,wyniki!$AX$7:$AY$54) -> #N/A | J41: =LOOKUP(K41,wyniki!$AX$7:$AY$54) -> #N/A | K41: =AE14 -> #N/A | N41: =AM15 | P41: =LOOKUP(N41,wyniki!$AX$7:$AY$54) -> #N/A | R41: =LOOKUP(S41,wyniki!$AX$7:$AY$54) -> #N/A | S41: =S15 | V41: =AI15 | X41: =LOOKUP(V41,wyniki!$AX$7:$AY$54) -> #N/A | Z41: =LOOKUP(AA41,wyniki!$AX$7:$AY$54) -> #N/A | AA41: =O15 | AD41: =AA15 | AF41: =LOOKUP(AD41,wyniki!$AX$7:$AY$54) -> #N/A | AX41: ABHI | AY41: =konkurs2!$K$16 | AZ41: =konkurs2!$AA$16 | BA41: =konkurs2!$S$16 | BB41: =konkurs2!$O$16 | BC41: =konkurs2!$AM$16 | BD41: =konkurs2!$W$16 | BE41: =konkurs2!$AU$16 | BF41: =konkurs2!$AQ$16 | BG41: =konkurs2!$C$16 | BH41: =konkurs2!$G$16 | BI41: =konkurs2!$AE$16 | BJ41: =konkurs2!$AI$16
AX42: ABHJ | AY42: =konkurs2!$K$16 | AZ42: =konkurs2!$AA$16 | BA42: =konkurs2!$S$16 | BB42: =konkurs2!$O$16 | BC42: =konkurs2!$AI$16 | BD42: =konkurs2!$W$16 | BE42: =konkurs2!$AU$16 | BF42: =konkurs2!$AQ$16 | BG42: =konkurs2!$C$16 | BH42: =konkurs2!$G$16 | BI42: =konkurs2!$AE$16 | BJ42: =konkurs2!$AM$16
...

Sheet zasady
B3: konkurs II - typowanie generalnych rozstrzygnięć
B4: za każdą drużynę na swoim miejscu w grupie | C4: 1 pkt
B5: za miejsca drużyn w drabince nie przyznaje się dodatkowych punktów
B6: za każdą drużynę w 1/16 finału | C6: 2 pkt
B7: za każdą drużynę w 1/8 finału | C7: 4 pkt
B8: za każdą drużynę w ćwierćfinale | C8: 6 pkt
B9: za każdą drużynę w półfinale | C9: 8 pkt
B10: za każdą drużynę w finale | C10: 10 pkt
B11: za mistrza swiata | C11: 12 pkt
B13: w przypadku tej samej liczby punktów, o wyższym miejscu w tabeli końcowej konkursu
B14: decyduje wieksza liczba zdobytów punktów w poźniejszej fazie mistrzostw
