Workbook

Sheet grup-1
E2: MŚ 2026 USA - MEKSYK - KANADA - faza grupowa - I runda, tura 1
B4: czwartek, 11 cze godz.21.00 | E4: Meksyk | K4: RPA | M4: Estadio Azteca, Mexico City, MEX
T5: 1 | U5: 2 | V5: 3 | W5: 4 | X5: 5 | Y5: 6 | Z5: 7 | AA5: 8 | AC5: 1 | AD5: 2 | AE5: 3 | AF5: 4 | AG5: 5 | AH5: 6 | AI5: 7 | AJ5: 8
C6: Grupa A | E6: Dario | F6: 1 | G6: 0 | H6: =T6 | K6: Talvik | L6: 2 | M6: 0 | N6: =AC6 | P6: Grupa E | T6: =IF($G$4="","",SUM(Y6:AA6)) | U6: =IF(V6>0,1,IF(V6=0,0,2)) -> 0 | V6: =$G$4-$H$4 -> 0 | W6: =IF(X6>0,1,IF(X6=0,0,2)) -> 1 | X6: =F6-G6 -> 1 | Y6: =IF(U6=W6,3,0) -> 0 | Z6: =IF(V6=X6,1,0) -> 0 | AA6: =IF(Z6=1,IF($G$4=F6,1,0),0) -> 0 | AC6: =IF($G$4="","",SUM(AH6:AJ6)) | AD6: =IF(AE6>0,1,IF(AE6=0,0,2)) -> 0 | AE6: =$G$4-$H$4 -> 0 | AF6: =IF(AG6>0,1,IF(AG6=0,0,2)) -> 1 | AG6: =L6-M6 -> 2 | AH6: =IF(AD6=AF6,3,0) -> 0 | AI6: =IF(AE6=AG6,1,0) -> 0 | AJ6: =IF(AI6=1,IF($G$4=L6,1,0),0) -> 0
E7: Wojtek | F7: 2 | G7: 1 | H7: =T7 | K7: Rafał | L7: 3 | M7: 0 | N7: =AC7 | T7: =IF($G$4="","",SUM(Y7:AA7)) | U7: =IF(V7>0,1,IF(V7=0,0,2)) -> 0 | V7: =$G$4-$H$4 -> 0 | W7: =IF(X7>0,1,IF(X7=0,0,2)) -> 1 | X7: =F7-G7 -> 1 | Y7: =IF(U7=W7,3,0) -> 0 | Z7: =IF(V7=X7,1,0) -> 0 | AA7: =IF(Z7=1,IF($G$4=F7,1,0),0) -> 0 | AC7: =IF($G$4="","",SUM(AH7:AJ7)) | AD7: =IF(AE7>0,1,IF(AE7=0,0,2)) -> 0 | AE7: =$G$4-$H$4 -> 0 | AF7: =IF(AG7>0,1,IF(AG7=0,0,2)) -> 1 | AG7: =L7-M7 -> 3 | AH7: =IF(AD7=AF7,3,0) -> 0 | AI7: =IF(AE7=AG7,1,0) -> 0 | AJ7: =IF(AI7=1,IF($G$4=L7,1,0),0) -> 0
E8: KamUla | F8: 2 | G8: 1 | H8: =T8 | K8: MarekS | L8: 2 | M8: 1 | N8: =AC8 | T8: =IF($G$4="","",SUM(Y8:AA8)) | U8: =IF(V8>0,1,IF(V8=0,0,2)) -> 0 | V8: =$G$4-$H$4 -> 0 | W8: =IF(X8>0,1,IF(X8=0,0,2)) -> 1 | X8: =F8-G8 -> 1 | Y8: =IF(U8=W8,3,0) -> 0 | Z8: =IF(V8=X8,1,0) -> 0 | AA8: =IF(Z8=1,IF($G$4=F8,1,0),0) -> 0 | AC8: =IF($G$4="","",SUM(AH8:AJ8)) | AD8: =IF(AE8>0,1,IF(AE8=0,0,2)) -> 0 | AE8: =$G$4-$H$4 -> 0 | AF8: =IF(AG8>0,1,IF(AG8=0,0,2)) -> 1 | AG8: =L8-M8 -> 1 | AH8: =IF(AD8=AF8,3,0) -> 0 | AI8: =IF(AE8=AG8,1,0) -> 0 | AJ8: =IF(AI8=1,IF($G$4=L8,1,0),0) -> 0
E9: MagdaS | F9: 2 | G9: 1 | H9: =T9 | K9: Karolina | L9: 2 | M9: 0 | N9: =AC9 | T9: =IF($G$4="","",SUM(Y9:AA9)) | U9: =IF(V9>0,1,IF(V9=0,0,2)) -> 0 | V9: =$G$4-$H$4 -> 0 | W9: =IF(X9>0,1,IF(X9=0,0,2)) -> 1 | X9: =F9-G9 -> 1 | Y9: =IF(U9=W9,3,0) -> 0 | Z9: =IF(V9=X9,1,0) -> 0 | AA9: =IF(Z9=1,IF($G$4=F9,1,0),0) -> 0 | AC9: =IF($G$4="","",SUM(AH9:AJ9)) | AD9: =IF(AE9>0,1,IF(AE9=0,0,2)) -> 0 | AE9: =$G$4-$H$4 -> 0 | AF9: =IF(AG9>0,1,IF(AG9=0,0,2)) -> 1 | AG9: =L9-M9 -> 2 | AH9: =IF(AD9=AF9,3,0) -> 0 | AI9: =IF(AE9=AG9,1,0) -> 0 | AJ9: =IF(AI9=1,IF($G$4=L9,1,0),0) -> 0
E10: KasiaJ | F10: 2 | G10: 0 | H10: =T10 | K10: AndrzejO | L10: 2 | M10: 0 | N10: =AC10 | T10: =IF($G$4="","",SUM(Y10:AA10)) | U10: =IF(V10>0,1,IF(V10=0,0,2)) -> 0 | V10: =$G$4-$H$4 -> 0 | W10: =IF(X10>0,1,IF(X10=0,0,2)) -> 1 | X10: =F10-G10 -> 2 | Y10: =IF(U10=W10,3,0) -> 0 | Z10: =IF(V10=X10,1,0) -> 0 | AA10: =IF(Z10=1,IF($G$4=F10,1,0),0) -> 0 | AC10: =IF($G$4="","",SUM(AH10:AJ10)) | AD10: =IF(AE10>0,1,IF(AE10=0,0,2)) -> 0 | AE10: =$G$4-$H$4 -> 0 | AF10: =IF(AG10>0,1,IF(AG10=0,0,2)) -> 1 | AG10: =L10-M10 -> 2 | AH10: =IF(AD10=AF10,3,0) -> 0 | AI10: =IF(AE10=AG10,1,0) -> 0 | AJ10: =IF(AI10=1,IF($G$4=L10,1,0),0) -> 0
E11: KrystianM | F11: 2 | G11: 0 | H11: =T11 | K11: PiotreM | L11: 3 | M11: 1 | N11: =AC11 | T11: =IF($G$4="","",SUM(Y11:AA11)) | U11: =IF(V11>0,1,IF(V11=0,0,2)) -> 0 | V11: =$G$4-$H$4 -> 0 | W11: =IF(X11>0,1,IF(X11=0,0,2)) -> 1 | X11: =F11-G11 -> 2 | Y11: =IF(U11=W11,3,0) -> 0 | Z11: =IF(V11=X11,1,0) -> 0 | AA11: =IF(Z11=1,IF($G$4=F11,1,0),0) -> 0 | AC11: =IF($G$4="","",SUM(AH11:AJ11)) | AD11: =IF(AE11>0,1,IF(AE11=0,0,2)) -> 0 | AE11: =$G$4-$H$4 -> 0 | AF11: =IF(AG11>0,1,IF(AG11=0,0,2)) -> 1 | AG11: =L11-M11 -> 2 | AH11: =IF(AD11=AF11,3,0) -> 0 | AI11: =IF(AE11=AG11,1,0) -> 0 | AJ11: =IF(AI11=1,IF($G$4=L11,1,0),0) -> 0
E12: PiotreG | F12: 0 | G12: 0 | H12: =T12 | K12: DarekJell | L12: 2 | M12: 0 | N12: =AC12 | T12: =IF($G$4="","",SUM(Y12:AA12)) | U12: =IF(V12>0,1,IF(V12=0,0,2)) -> 0 | V12: =$G$4-$H$4 -> 0 | W12: =IF(X12>0,1,IF(X12=0,0,2)) -> 0 | X12: =F12-G12 -> 0 | Y12: =IF(U12=W12,3,0) -> 3 | Z12: =IF(V12=X12,1,0) -> 1 | AA12: =IF(Z12=1,IF($G$4=F12,1,0),0) -> 1 | AC12: =IF($G$4="","",SUM(AH12:AJ12)) | AD12: =IF(AE12>0,1,IF(AE12=0,0,2)) -> 0 | AE12: =$G$4-$H$4 -> 0 | AF12: =IF(AG12>0,1,IF(AG12=0,0,2)) -> 1 | AG12: =L12-M12 -> 2 | AH12: =IF(AD12=AF12,3,0) -> 0 | AI12: =IF(AE12=AG12,1,0) -> 0 | AJ12: =IF(AI12=1,IF($G$4=L12,1,0),0) -> 0
C13: Grupa B | E13: Prozped | F13: 3 | G13: 1 | H13: =T13 | K13: MaciejM | L13: 2 | M13: 0 | N13: =AC13 | P13: Grupa F | T13: =IF($G$4="","",SUM(Y13:AA13)) | U13: =IF(V13>0,1,IF(V13=0,0,2)) -> 0 | V13: =$G$4-$H$4 -> 0 | W13: =IF(X13>0,1,IF(X13=0,0,2)) -> 1 | X13: =F13-G13 -> 2 | Y13: =IF(U13=W13,3,0) -> 0 | Z13: =IF(V13=X13,1,0) -> 0 | AA13: =IF(Z13=1,IF($G$4=F13,1,0),0) -> 0 | AC13: =IF($G$4="","",SUM(AH13:AJ13)) | AD13: =IF(AE13>0,1,IF(AE13=0,0,2)) -> 0 | AE13: =$G$4-$H$4 -> 0 | AF13: =IF(AG13>0,1,IF(AG13=0,0,2)) -> 1 | AG13: =L13-M13 -> 2 | AH13: =IF(AD13=AF13,3,0) -> 0 | AI13: =IF(AE13=AG13,1,0) -> 0 | AJ13: =IF(AI13=1,IF($G$4=L13,1,0),0) -> 0
E14: Artur | F14: 2 | G14: 1 | H14: =T14 | K14: KSZ | L14: 1 | M14: 0 | N14: =AC14 | T14: =IF($G$4="","",SUM(Y14:AA14)) | U14: =IF(V14>0,1,IF(V14=0,0,2)) -> 0 | V14: =$G$4-$H$4 -> 0 | W14: =IF(X14>0,1,IF(X14=0,0,2)) -> 1 | X14: =F14-G14 -> 1 | Y14: =IF(U14=W14,3,0) -> 0 | Z14: =IF(V14=X14,1,0) -> 0 | AA14: =IF(Z14=1,IF($G$4=F14,1,0),0) -> 0 | AC14: =IF($G$4="","",SUM(AH14:AJ14)) | AD14: =IF(AE14>0,1,IF(AE14=0,0,2)) -> 0 | AE14: =$G$4-$H$4 -> 0 | AF14: =IF(AG14>0,1,IF(AG14=0,0,2)) -> 1 | AG14: =L14-M14 -> 1 | AH14: =IF(AD14=AF14,3,0) -> 0 | AI14: =IF(AE14=AG14,1,0) -> 0 | AJ14: =IF(AI14=1,IF($G$4=L14,1,0),0) -> 0
E15: Sokółka | F15: 2 | G15: 1 | H15: =T15 | K15: MarekP | L15: 2 | M15: 1 | N15: =AC15 | T15: =IF($G$4="","",SUM(Y15:AA15)) | U15: =IF(V15>0,1,IF(V15=0,0,2)) -> 0 | V15: =$G$4-$H$4 -> 0 | W15: =IF(X15>0,1,IF(X15=0,0,2)) -> 1 | X15: =F15-G15 -> 1 | Y15: =IF(U15=W15,3,0) -> 0 | Z15: =IF(V15=X15,1,0) -> 0 | AA15: =IF(Z15=1,IF($G$4=F15,1,0),0) -> 0 | AC15: =IF($G$4="","",SUM(AH15:AJ15)) | AD15: =IF(AE15>0,1,IF(AE15=0,0,2)) -> 0 | AE15: =$G$4-$H$4 -> 0 | AF15: =IF(AG15>0,1,IF(AG15=0,0,2)) -> 1 | AG15: =L15-M15 -> 1 | AH15: =IF(AD15=AF15,3,0) -> 0 | AI15: =IF(AE15=AG15,1,0) -> 0 | AJ15: =IF(AI15=1,IF($G$4=L15,1,0),0) -> 0
E16: KasiaK | F16: 3 | G16: 1 | H16: =T16 | K16: KleoPatra | L16: 2 | M16: 1 | N16: =AC16 | T16: =IF($G$4="","",SUM(Y16:AA16)) | U16: =IF(V16>0,1,IF(V16=0,0,2)) -> 0 | V16: =$G$4-$H$4 -> 0 | W16: =IF(X16>0,1,IF(X16=0,0,2)) -> 1 | X16: =F16-G16 -> 2 | Y16: =IF(U16=W16,3,0) -> 0 | Z16: =IF(V16=X16,1,0) -> 0 | AA16: =IF(Z16=1,IF($G$4=F16,1,0),0) -> 0 | AC16: =IF($G$4="","",SUM(AH16:AJ16)) | AD16: =IF(AE16>0,1,IF(AE16=0,0,2)) -> 0 | AE16: =$G$4-$H$4 -> 0 | AF16: =IF(AG16>0,1,IF(AG16=0,0,2)) -> 1 | AG16: =L16-M16 -> 1 | AH16: =IF(AD16=AF16,3,0) -> 0 | AI16: =IF(AE16=AG16,1,0) -> 0 | AJ16: =IF(AI16=1,IF($G$4=L16,1,0),0) -> 0
E17: Seweryn | F17: 3 | G17: 1 | H17: =T17 | K17: MichałeK | L17: 3 | M17: 0 | N17: =AC17 | T17: =IF($G$4="","",SUM(Y17:AA17)) | U17: =IF(V17>0,1,IF(V17=0,0,2)) -> 0 | V17: =$G$4-$H$4 -> 0 | W17: =IF(X17>0,1,IF(X17=0,0,2)) -> 1 | X17: =F17-G17 -> 2 | Y17: =IF(U17=W17,3,0) -> 0 | Z17: =IF(V17=X17,1,0) -> 0 | AA17: =IF(Z17=1,IF($G$4=F17,1,0),0) -> 0 | AC17: =IF($G$4="","",SUM(AH17:AJ17)) | AD17: =IF(AE17>0,1,IF(AE17=0,0,2)) -> 0 | AE17: =$G$4-$H$4 -> 0 | AF17: =IF(AG17>0,1,IF(AG17=0,0,2)) -> 1 | AG17: =L17-M17 -> 3 | AH17: =IF(AD17=AF17,3,0) -> 0 | AI17: =IF(AE17=AG17,1,0) -> 0 | AJ17: =IF(AI17=1,IF($G$4=L17,1,0),0) -> 0
E18: DarekL | F18: 2 | G18: 0 | H18: =T18 | K18: Witek | L18: 2 | M18: 1 | N18: =AC18 | T18: =IF($G$4="","",SUM(Y18:AA18)) | U18: =IF(V18>0,1,IF(V18=0,0,2)) -> 0 | V18: =$G$4-$H$4 -> 0 | W18: =IF(X18>0,1,IF(X18=0,0,2)) -> 1 | X18: =F18-G18 -> 2 | Y18: =IF(U18=W18,3,0) -> 0 | Z18: =IF(V18=X18,1,0) -> 0 | AA18: =IF(Z18=1,IF($G$4=F18,1,0),0) -> 0 | AC18: =IF($G$4="","",SUM(AH18:AJ18)) | AD18: =IF(AE18>0,1,IF(AE18=0,0,2)) -> 0 | AE18: =$G$4-$H$4 -> 0 | AF18: =IF(AG18>0,1,IF(AG18=0,0,2)) -> 1 | AG18: =L18-M18 -> 1 | AH18: =IF(AD18=AF18,3,0) -> 0 | AI18: =IF(AE18=AG18,1,0) -> 0 | AJ18: =IF(AI18=1,IF($G$4=L18,1,0),0) -> 0
E19: KrzysztoW | F19: 2 | G19: 0 | H19: =T19 | K19: RobertLat | L19: 1 | M19: 1 | N19: =AC19 | T19: =IF($G$4="","",SUM(Y19:AA19)) | U19: =IF(V19>0,1,IF(V19=0,0,2)) -> 0 | V19: =$G$4-$H$4 -> 0 | W19: =IF(X19>0,1,IF(X19=0,0,2)) -> 1 | X19: =F19-G19 -> 2 | Y19: =IF(U19=W19,3,0) -> 0 | Z19: =IF(V19=X19,1,0) -> 0 | AA19: =IF(Z19=1,IF($G$4=F19,1,0),0) -> 0 | AC19: =IF($G$4="","",SUM(AH19:AJ19)) | AD19: =IF(AE19>0,1,IF(AE19=0,0,2)) -> 0 | AE19: =$G$4-$H$4 -> 0 | AF19: =IF(AG19>0,1,IF(AG19=0,0,2)) -> 0 | AG19: =L19-M19 -> 0 | AH19: =IF(AD19=AF19,3,0) -> 3 | AI19: =IF(AE19=AG19,1,0) -> 1 | AJ19: =IF(AI19=1,IF($G$4=L19,1,0),0) -> 0
C20: Grupa C | E20: Magiera | F20: 2 | G20: 0 | H20: =T20 | K20: DeDe | L20: 2 | M20: 0 | N20: =AC20 | P20: Grupa G | T20: =IF($G$4="","",SUM(Y20:AA20)) | U20: =IF(V20>0,1,IF(V20=0,0,2)) -> 0 | V20: =$G$4-$H$4 -> 0 | W20: =IF(X20>0,1,IF(X20=0,0,2)) -> 1 | X20: =F20-G20 -> 2 | Y20: =IF(U20=W20,3,0) -> 0 | Z20: =IF(V20=X20,1,0) -> 0 | AA20: =IF(Z20=1,IF($G$4=F20,1,0),0) -> 0 | AC20: =IF($G$4="","",SUM(AH20:AJ20)) | AD20: =IF(AE20>0,1,IF(AE20=0,0,2)) -> 0 | AE20: =$G$4-$H$4 -> 0 | AF20: =IF(AG20>0,1,IF(AG20=0,0,2)) -> 1 | AG20: =L20-M20 -> 2 | AH20: =IF(AD20=AF20,3,0) -> 0 | AI20: =IF(AE20=AG20,1,0) -> 0 | AJ20: =IF(AI20=1,IF($G$4=L20,1,0),0) -> 0
E21: Henryk | F21: 2 | G21: 1 | H21: =T21 | K21: Cypryjka | L21: 2 | M21: 1 | N21: =AC21 | T21: =IF($G$4="","",SUM(Y21:AA21)) | U21: =IF(V21>0,1,IF(V21=0,0,2)) -> 0 | V21: =$G$4-$H$4 -> 0 | W21: =IF(X21>0,1,IF(X21=0,0,2)) -> 1 | X21: =F21-G21 -> 1 | Y21: =IF(U21=W21,3,0) -> 0 | Z21: =IF(V21=X21,1,0) -> 0 | AA21: =IF(Z21=1,IF($G$4=F21,1,0),0) -> 0 | AC21: =IF($G$4="","",SUM(AH21:AJ21)) | AD21: =IF(AE21>0,1,IF(AE21=0,0,2)) -> 0 | AE21: =$G$4-$H$4 -> 0 | AF21: =IF(AG21>0,1,IF(AG21=0,0,2)) -> 1 | AG21: =L21-M21 -> 1 | AH21: =IF(AD21=AF21,3,0) -> 0 | AI21: =IF(AE21=AG21,1,0) -> 0 | AJ21: =IF(AI21=1,IF($G$4=L21,1,0),0) -> 0
E22: PPP | F22: 2 | G22: 0 | H22: =T22 | K22: Tabus | L22: 3 | M22: 1 | N22: =AC22 | T22: =IF($G$4="","",SUM(Y22:AA22)) | U22: =IF(V22>0,1,IF(V22=0,0,2)) -> 0 | V22: =$G$4-$H$4 -> 0 | W22: =IF(X22>0,1,IF(X22=0,0,2)) -> 1 | X22: =F22-G22 -> 2 | Y22: =IF(U22=W22,3,0) -> 0 | Z22: =IF(V22=X22,1,0) -> 0 | AA22: =IF(Z22=1,IF($G$4=F22,1,0),0) -> 0 | AC22: =IF($G$4="","",SUM(AH22:AJ22)) | AD22: =IF(AE22>0,1,IF(AE22=0,0,2)) -> 0 | AE22: =$G$4-$H$4 -> 0 | AF22: =IF(AG22>0,1,IF(AG22=0,0,2)) -> 1 | AG22: =L22-M22 -> 2 | AH22: =IF(AD22=AF22,3,0) -> 0 | AI22: =IF(AE22=AG22,1,0) -> 0 | AJ22: =IF(AI22=1,IF($G$4=L22,1,0),0) -> 0
E23: Żaklina | F23: 2 | G23: 0 | H23: =T23 | K23: AniaS | L23: 3 | M23: 1 | N23: =AC23 | T23: =IF($G$4="","",SUM(Y23:AA23)) | U23: =IF(V23>0,1,IF(V23=0,0,2)) -> 0 | V23: =$G$4-$H$4 -> 0 | W23: =IF(X23>0,1,IF(X23=0,0,2)) -> 1 | X23: =F23-G23 -> 2 | Y23: =IF(U23=W23,3,0) -> 0 | Z23: =IF(V23=X23,1,0) -> 0 | AA23: =IF(Z23=1,IF($G$4=F23,1,0),0) -> 0 | AC23: =IF($G$4="","",SUM(AH23:AJ23)) | AD23: =IF(AE23>0,1,IF(AE23=0,0,2)) -> 0 | AE23: =$G$4-$H$4 -> 0 | AF23: =IF(AG23>0,1,IF(AG23=0,0,2)) -> 1 | AG23: =L23-M23 -> 2 | AH23: =IF(AD23=AF23,3,0) -> 0 | AI23: =IF(AE23=AG23,1,0) -> 0 | AJ23: =IF(AI23=1,IF($G$4=L23,1,0),0) -> 0
E24: Cezary | F24: 2 | G24: 1 | H24: =T24 | K24: Pimozid | L24: 2 | M24: 1 | N24: =AC24 | T24: =IF($G$4="","",SUM(Y24:AA24)) | U24: =IF(V24>0,1,IF(V24=0,0,2)) -> 0 | V24: =$G$4-$H$4 -> 0 | W24: =IF(X24>0,1,IF(X24=0,0,2)) -> 1 | X24: =F24-G24 -> 1 | Y24: =IF(U24=W24,3,0) -> 0 | Z24: =IF(V24=X24,1,0) -> 0 | AA24: =IF(Z24=1,IF($G$4=F24,1,0),0) -> 0 | AC24: =IF($G$4="","",SUM(AH24:AJ24)) | AD24: =IF(AE24>0,1,IF(AE24=0,0,2)) -> 0 | AE24: =$G$4-$H$4 -> 0 | AF24: =IF(AG24>0,1,IF(AG24=0,0,2)) -> 1 | AG24: =L24-M24 -> 1 | AH24: =IF(AD24=AF24,3,0) -> 0 | AI24: =IF(AE24=AG24,1,0) -> 0 | AJ24: =IF(AI24=1,IF($G$4=L24,1,0),0) -> 0
E25: Dziobak | F25: 3 | G25: 1 | H25: =T25 | K25: KrzysztoWś | L25: 1 | M25: 1 | N25: =AC25 | T25: =IF($G$4="","",SUM(Y25:AA25)) | U25: =IF(V25>0,1,IF(V25=0,0,2)) -> 0 | V25: =$G$4-$H$4 -> 0 | W25: =IF(X25>0,1,IF(X25=0,0,2)) -> 1 | X25: =F25-G25 -> 2 | Y25: =IF(U25=W25,3,0) -> 0 | Z25: =IF(V25=X25,1,0) -> 0 | AA25: =IF(Z25=1,IF($G$4=F25,1,0),0) -> 0 | AC25: =IF($G$4="","",SUM(AH25:AJ25)) | AD25: =IF(AE25>0,1,IF(AE25=0,0,2)) -> 0 | AE25: =$G$4-$H$4 -> 0 | AF25: =IF(AG25>0,1,IF(AG25=0,0,2)) -> 0 | AG25: =L25-M25 -> 0 | AH25: =IF(AD25=AF25,3,0) -> 3 | AI25: =IF(AE25=AG25,1,0) -> 1 | AJ25: =IF(AI25=1,IF($G$4=L25,1,0),0) -> 0
E26: MateuszKn | F26: 2 | G26: 1 | H26: =T26 | K26: Ruslan | L26: 2 | M26: 0 | N26: =AC26 | T26: =IF($G$4="","",SUM(Y26:AA26)) | U26: =IF(V26>0,1,IF(V26=0,0,2)) -> 0 | V26: =$G$4-$H$4 -> 0 | W26: =IF(X26>0,1,IF(X26=0,0,2)) -> 1 | X26: =F26-G26 -> 1 | Y26: =IF(U26=W26,3,0) -> 0 | Z26: =IF(V26=X26,1,0) -> 0 | AA26: =IF(Z26=1,IF($G$4=F26,1,0),0) -> 0 | AC26: =IF($G$4="","",SUM(AH26:AJ26)) | AD26: =IF(AE26>0,1,IF(AE26=0,0,2)) -> 0 | AE26: =$G$4-$H$4 -> 0 | AF26: =IF(AG26>0,1,IF(AG26=0,0,2)) -> 1 | AG26: =L26-M26 -> 2 | AH26: =IF(AD26=AF26,3,0) -> 0 | AI26: =IF(AE26=AG26,1,0) -> 0 | AJ26: =IF(AI26=1,IF($G$4=L26,1,0),0) -> 0
C27: Grupa D | E27: Przemek | F27: 2 | G27: 1 | H27: =T27 | K27: PiotreK | L27: 2 | M27: 0 | N27: =AC27 | P27: Grupa H | T27: =IF($G$4="","",SUM(Y27:AA27)) | U27: =IF(V27>0,1,IF(V27=0,0,2)) -> 0 | V27: =$G$4-$H$4 -> 0 | W27: =IF(X27>0,1,IF(X27=0,0,2)) -> 1 | X27: =F27-G27 -> 1 | Y27: =IF(U27=W27,3,0) -> 0 | Z27: =IF(V27=X27,1,0) -> 0 | AA27: =IF(Z27=1,IF($G$4=F27,1,0),0) -> 0 | AC27: =IF($G$4="","",SUM(AH27:AJ27)) | AD27: =IF(AE27>0,1,IF(AE27=0,0,2)) -> 0 | AE27: =$G$4-$H$4 -> 0 | AF27: =IF(AG27>0,1,IF(AG27=0,0,2)) -> 1 | AG27: =L27-M27 -> 2 | AH27: =IF(AD27=AF27,3,0) -> 0 | AI27: =IF(AE27=AG27,1,0) -> 0 | AJ27: =IF(AI27=1,IF($G$4=L27,1,0),0) -> 0
E28: Borys | F28: 1 | G28: 0 | H28: =T28 | K28: KaBed | L28: 2 | M28: 0 | N28: =AC28 | T28: =IF($G$4="","",SUM(Y28:AA28)) | U28: =IF(V28>0,1,IF(V28=0,0,2)) -> 0 | V28: =$G$4-$H$4 -> 0 | W28: =IF(X28>0,1,IF(X28=0,0,2)) -> 1 | X28: =F28-G28 -> 1 | Y28: =IF(U28=W28,3,0) -> 0 | Z28: =IF(V28=X28,1,0) -> 0 | AA28: =IF(Z28=1,IF($G$4=F28,1,0),0) -> 0 | AC28: =IF($G$4="","",SUM(AH28:AJ28)) | AD28: =IF(AE28>0,1,IF(AE28=0,0,2)) -> 0 | AE28: =$G$4-$H$4 -> 0 | AF28: =IF(AG28>0,1,IF(AG28=0,0,2)) -> 1 | AG28: =L28-M28 -> 2 | AH28: =IF(AD28=AF28,3,0) -> 0 | AI28: =IF(AE28=AG28,1,0) -> 0 | AJ28: =IF(AI28=1,IF($G$4=L28,1,0),0) -> 0
E29: Turbo-Ryżu | F29: 2 | G29: 0 | H29: =T29 | K29: Mirella | L29: 3 | M29: 1 | N29: =AC29 | T29: =IF($G$4="","",SUM(Y29:AA29)) | U29: =IF(V29>0,1,IF(V29=0,0,2)) -> 0 | V29: =$G$4-$H$4 -> 0 | W29: =IF(X29>0,1,IF(X29=0,0,2)) -> 1 | X29: =F29-G29 -> 2 | Y29: =IF(U29=W29,3,0) -> 0 | Z29: =IF(V29=X29,1,0) -> 0 | AA29: =IF(Z29=1,IF($G$4=F29,1,0),0) -> 0 | AC29: =IF($G$4="","",SUM(AH29:AJ29)) | AD29: =IF(AE29>0,1,IF(AE29=0,0,2)) -> 0 | AE29: =$G$4-$H$4 -> 0 | AF29: =IF(AG29>0,1,IF(AG29=0,0,2)) -> 1 | AG29: =L29-M29 -> 2 | AH29: =IF(AD29=AF29,3,0) -> 0 | AI29: =IF(AE29=AG29,1,0) -> 0 | AJ29: =IF(AI29=1,IF($G$4=L29,1,0),0) -> 0
E30: MagdaP | F30: 1 | G30: 0 | H30: =T30 | K30: Maria | L30: 2 | M30: 1 | N30: =AC30 | T30: =IF($G$4="","",SUM(Y30:AA30)) | U30: =IF(V30>0,1,IF(V30=0,0,2)) -> 0 | V30: =$G$4-$H$4 -> 0 | W30: =IF(X30>0,1,IF(X30=0,0,2)) -> 1 | X30: =F30-G30 -> 1 | Y30: =IF(U30=W30,3,0) -> 0 | Z30: =IF(V30=X30,1,0) -> 0 | AA30: =IF(Z30=1,IF($G$4=F30,1,0),0) -> 0 | AC30: =IF($G$4="","",SUM(AH30:AJ30)) | AD30: =IF(AE30>0,1,IF(AE30=0,0,2)) -> 0 | AE30: =$G$4-$H$4 -> 0 | AF30: =IF(AG30>0,1,IF(AG30=0,0,2)) -> 1 | AG30: =L30-M30 -> 1 | AH30: =IF(AD30=AF30,3,0) -> 0 | AI30: =IF(AE30=AG30,1,0) -> 0 | AJ30: =IF(AI30=1,IF($G$4=L30,1,0),0) -> 0
E31: Małgorzata | F31: 2 | G31: 0 | H31: =T31 | K31: Sławek | L31: 2 | M31: 1 | N31: =AC31 | T31: =IF($G$4="","",SUM(Y31:AA31)) | U31: =IF(V31>0,1,IF(V31=0,0,2)) -> 0 | V31: =$G$4-$H$4 -> 0 | W31: =IF(X31>0,1,IF(X31=0,0,2)) -> 1 | X31: =F31-G31 -> 2 | Y31: =IF(U31=W31,3,0) -> 0 | Z31: =IF(V31=X31,1,0) -> 0 | AA31: =IF(Z31=1,IF($G$4=F31,1,0),0) -> 0 | AC31: =IF($G$4="","",SUM(AH31:AJ31)) | AD31: =IF(AE31>0,1,IF(AE31=0,0,2)) -> 0 | AE31: =$G$4-$H$4 -> 0 | AF31: =IF(AG31>0,1,IF(AG31=0,0,2)) -> 1 | AG31: =L31-M31 -> 1 | AH31: =IF(AD31=AF31,3,0) -> 0 | AI31: =IF(AE31=AG31,1,0) -> 0 | AJ31: =IF(AI31=1,IF($G$4=L31,1,0),0) -> 0
E32: KamilF | F32: 2 | G32: 1 | H32: =T32 | K32: PawełSt | L32: 3 | M32: 2 | N32: =AC32 | T32: =IF($G$4="","",SUM(Y32:AA32)) | U32: =IF(V32>0,1,IF(V32=0,0,2)) -> 0 | V32: =$G$4-$H$4 -> 0 | W32: =IF(X32>0,1,IF(X32=0,0,2)) -> 1 | X32: =F32-G32 -> 1 | Y32: =IF(U32=W32,3,0) -> 0 | Z32: =IF(V32=X32,1,0) -> 0 | AA32: =IF(Z32=1,IF($G$4=F32,1,0),0) -> 0 | AC32: =IF($G$4="","",SUM(AH32:AJ32)) | AD32: =IF(AE32>0,1,IF(AE32=0,0,2)) -> 0 | AE32: =$G$4-$H$4 -> 0 | AF32: =IF(AG32>0,1,IF(AG32=0,0,2)) -> 1 | AG32: =L32-M32 -> 1 | AH32: =IF(AD32=AF32,3,0) -> 0 | AI32: =IF(AE32=AG32,1,0) -> 0 | AJ32: =IF(AI32=1,IF($G$4=L32,1,0),0) -> 0
E33: MichałCz | F33: 2 | G33: 0 | H33: =T33 | K33: KrzysztofeR | L33: 3 | M33: 1 | N33: =AC33 | T33: =IF($G$4="","",SUM(Y33:AA33)) | U33: =IF(V33>0,1,IF(V33=0,0,2)) -> 0 | V33: =$G$4-$H$4 -> 0 | W33: =IF(X33>0,1,IF(X33=0,0,2)) -> 1 | X33: =F33-G33 -> 2 | Y33: =IF(U33=W33,3,0) -> 0 | Z33: =IF(V33=X33,1,0) -> 0 | AA33: =IF(Z33=1,IF($G$4=F33,1,0),0) -> 0 | AC33: =IF($G$4="","",SUM(AH33:AJ33)) | AD33: =IF(AE33>0,1,IF(AE33=0,0,2)) -> 0 | AE33: =$G$4-$H$4 -> 0 | AF33: =IF(AG33>0,1,IF(AG33=0,0,2)) -> 1 | AG33: =L33-M33 -> 2 | AH33: =IF(AD33=AF33,3,0) -> 0 | AI33: =IF(AE33=AG33,1,0) -> 0 | AJ33: =IF(AI33=1,IF($G$4=L33,1,0),0) -> 0
B35: piątek, 12 cze godz. 04.00 | E35: Korea Płd. | K35: Czechy
C37: Grupa A | E37: Dario | F37: 1 | G37: 1 | K37: Talvik | L37: 2 | M37: 1 | N37: =AC37 | P37: Grupa E | T37: =IF($G$35="","",SUM(Y37:AA37)) | U37: =IF(V37>0,1,IF(V37=0,0,2)) -> 0 | V37: =$G$35-$H$35 -> 0 | W37: =IF(X37>0,1,IF(X37=0,0,2)) -> 0 | X37: =F37-G37 -> 0 | Y37: =IF(U37=W37,3,0) -> 3 | Z37: =IF(V37=X37,1,0) -> 1 | AA37: =IF(Z37=1,IF($G$35=F37,1,0),0) -> 0 | AC37: =IF($G$35="","",SUM(AH37:AJ37)) | AD37: =IF(AE37>0,1,IF(AE37=0,0,2)) -> 0 | AE37: =$G$35-$H$35 -> 0 | AF37: =IF(AG37>0,1,IF(AG37=0,0,2)) -> 1 | AG37: =L37-M37 -> 1 | AH37: =IF(AD37=AF37,3,0) -> 0 | AI37: =IF(AE37=AG37,1,0) -> 0 | AJ37: =IF(AI37=1,IF($G$35=L37,1,0),0) -> 0
E38: Wojtek | F38: 1 | G38: 1 | K38: Rafał | L38: 2 | M38: 3 | N38: =AC38 | T38: =IF($G$35="","",SUM(Y38:AA38)) | U38: =IF(V38>0,1,IF(V38=0,0,2)) -> 0 | V38: =$G$35-$H$35 -> 0 | W38: =IF(X38>0,1,IF(X38=0,0,2)) -> 0 | X38: =F38-G38 -> 0 | Y38: =IF(U38=W38,3,0) -> 3 | Z38: =IF(V38=X38,1,0) -> 1 | AA38: =IF(Z38=1,IF($G$35=F38,1,0),0) -> 0 | AC38: =IF($G$35="","",SUM(AH38:AJ38)) | AD38: =IF(AE38>0,1,IF(AE38=0,0,2)) -> 0 | AE38: =$G$35-$H$35 -> 0 | AF38: =IF(AG38>0,1,IF(AG38=0,0,2)) -> 2 | AG38: =L38-M38 -> -1 | AH38: =IF(AD38=AF38,3,0) -> 0 | AI38: =IF(AE38=AG38,1,0) -> 0 | AJ38: =IF(AI38=1,IF($G$35=L38,1,0),0) -> 0
E39: KamUla | F39: 1 | G39: 1 | K39: MarekS | L39: 1 | M39: 1 | N39: =AC39 | T39: =IF($G$35="","",SUM(Y39:AA39)) | U39: =IF(V39>0,1,IF(V39=0,0,2)) -> 0 | V39: =$G$35-$H$35 -> 0 | W39: =IF(X39>0,1,IF(X39=0,0,2)) -> 0 | X39: =F39-G39 -> 0 | Y39: =IF(U39=W39,3,0) -> 3 | Z39: =IF(V39=X39,1,0) -> 1 | AA39: =IF(Z39=1,IF($G$35=F39,1,0),0) -> 0 | AC39: =IF($G$35="","",SUM(AH39:AJ39)) | AD39: =IF(AE39>0,1,IF(AE39=0,0,2)) -> 0 | AE39: =$G$35-$H$35 -> 0 | AF39: =IF(AG39>0,1,IF(AG39=0,0,2)) -> 0 | AG39: =L39-M39 -> 0 | AH39: =IF(AD39=AF39,3,0) -> 3 | AI39: =IF(AE39=AG39,1,0) -> 1 | AJ39: =IF(AI39=1,IF($G$35=L39,1,0),0) -> 0
E40: MagdaS | F40: 0 | G40: 1 | K40: Karolina | L40: 1 | M40: 1 | N40: =AC40 | T40: =IF($G$35="","",SUM(Y40:AA40)) | U40: =IF(V40>0,1,IF(V40=0,0,2)) -> 0 | V40: =$G$35-$H$35 -> 0 | W40: =IF(X40>0,1,IF(X40=0,0,2)) -> 2 | X40: =F40-G40 -> -1 | Y40: =IF(U40=W40,3,0) -> 0 | Z40: =IF(V40=X40,1,0) -> 0 | AA40: =IF(Z40=1,IF($G$35=F40,1,0),0) -> 0 | AC40: =IF($G$35="","",SUM(AH40:AJ40)) | AD40: =IF(AE40>0,1,IF(AE40=0,0,2)) -> 0 | AE40: =$G$35-$H$35 -> 0 | AF40: =IF(AG40>0,1,IF(AG40=0,0,2)) -> 0 | AG40: =L40-M40 -> 0 | AH40: =IF(AD40=AF40,3,0) -> 3 | AI40: =IF(AE40=AG40,1,0) -> 1 | AJ40: =IF(AI40=1,IF($G$35=L40,1,0),0) -> 0
E41: KasiaJ | F41: 1 | G41: 2 | K41: AndrzejO | L41: 1 | M41: 1 | N41: =AC41 | T41: =IF($G$35="","",SUM(Y41:AA41)) | U41: =IF(V41>0,1,IF(V41=0,0,2)) -> 0 | V41: =$G$35-$H$35 -> 0 | W41: =IF(X41>0,1,IF(X41=0,0,2)) -> 2 | X41: =F41-G41 -> -1 | Y41: =IF(U41=W41,3,0) -> 0 | Z41: =IF(V41=X41,1,0) -> 0 | AA41: =IF(Z41=1,IF($G$35=F41,1,0),0) -> 0 | AC41: =IF($G$35="","",SUM(AH41:AJ41)) | AD41: =IF(AE41>0,1,IF(AE41=0,0,2)) -> 0 | AE41: =$G$35-$H$35 -> 0 | AF41: =IF(AG41>0,1,IF(AG41=0,0,2)) -> 0 | AG41: =L41-M41 -> 0 | AH41: =IF(AD41=AF41,3,0) -> 3 | AI41: =IF(AE41=AG41,1,0) -> 1 | AJ41: =IF(AI41=1,IF($G$35=L41,1,0),0) -> 0
E42: KrystianM | F42: 1 | G42: 2 | K42: PiotreM | L42: 1 | M42: 2 | N42: =AC42 | T42: =IF($G$35="","",SUM(Y42:AA42)) | U42: =IF(V42>0,1,IF(V42=0,0,2)) -> 0 | V42: =$G$35-$H$35 -> 0 | W42: =IF(X42>0,1,IF(X42=0,0,2)) -> 2 | X42: =F42-G42 -> -1 | Y42: =IF(U42=W42,3,0) -> 0 | Z42: =IF(V42=X42,1,0) -> 0 | AA42: =IF(Z42=1,IF($G$35=F42,1,0),0) -> 0 | AC42: =IF($G$35="","",SUM(AH42:AJ42)) | AD42: =IF(AE42>0,1,IF(AE42=0,0,2)) -> 0 | AE42: =$G$35-$H$35 -> 0 | AF42: =IF(AG42>0,1,IF(AG42=0,0,2)) -> 2 | AG42: =L42-M42 -> -1 | AH42: =IF(AD42=AF42,3,0) -> 0 | AI42: =IF(AE42=AG42,1,0) -> 0 | AJ42: =IF(AI42=1,IF($G$35=L42,1,0),0) -> 0
E43: PiotreG | F43: 1 | G43: 0 | K43: DarekJell | L43: 2 | M43: 1 | N43: =AC43 | T43: =IF($G$35="","",SUM(Y43:AA43)) | U43: =IF(V43>0,1,IF(V43=0,0,2)) -> 0 | V43: =$G$35-$H$35 -> 0 | W43: =IF(X43>0,1,IF(X43=0,0,2)) -> 1 | X43: =F43-G43 -> 1 | Y43: =IF(U43=W43,3,0) -> 0 | Z43: =IF(V43=X43,1,0) -> 0 | AA43: =IF(Z43=1,IF($G$35=F43,1,0),0) -> 0 | AC43: =IF($G$35="","",SUM(AH43:AJ43)) | AD43: =IF(AE43>0,1,IF(AE43=0,0,2)) -> 0 | AE43: =$G$35-$H$35 -> 0 | AF43: =IF(AG43>0,1,IF(AG43=0,0,2)) -> 1 | AG43: =L43-M43 -> 1 | AH43: =IF(AD43=AF43,3,0) -> 0 | AI43: =IF(AE43=AG43,1,0) -> 0 | AJ43: =IF(AI43=1,IF($G$35=L43,1,0),0) -> 0
C44: Grupa B | E44: Prozped | F44: 1 | G44: 1 | K44: MaciejM | L44: 1 | M44: 1 | N44: =AC44 | P44: Grupa F | T44: =IF($G$35="","",SUM(Y44:AA44)) | U44: =IF(V44>0,1,IF(V44=0,0,2)) -> 0 | V44: =$G$35-$H$35 -> 0 | W44: =IF(X44>0,1,IF(X44=0,0,2)) -> 0 | X44: =F44-G44 -> 0 | Y44: =IF(U44=W44,3,0) -> 3 | Z44: =IF(V44=X44,1,0) -> 1 | AA44: =IF(Z44=1,IF($G$35=F44,1,0),0) -> 0 | AC44: =IF($G$35="","",SUM(AH44:AJ44)) | AD44: =IF(AE44>0,1,IF(AE44=0,0,2)) -> 0 | AE44: =$G$35-$H$35 -> 0 | AF44: =IF(AG44>0,1,IF(AG44=0,0,2)) -> 0 | AG44: =L44-M44 -> 0 | AH44: =IF(AD44=AF44,3,0) -> 3 | AI44: =IF(AE44=AG44,1,0) -> 1 | AJ44: =IF(AI44=1,IF($G$35=L44,1,0),0) -> 0
...

Sheet tab grup
C1: MŚ 2026 USA - MEKSYK - KANADA - Tabele grupowe Konkursu I-go | X1: meczów: | Z1: ='r1'!AE2 -> 1
B3: =SUM(D4:D10) -> 0 | C3: Grupa A | D3: pkt | E3: 3p | F3: 4p | G3: 5p | H3: % | I3: grup I | J3: grup II | K3: grup III | M3: bns | O3: =SUM(Q4:Q10) -> 0 | P3: Grupa A | Q3: pkt | R3: 3p | S3: 4p | T3: 5p | U3: % | V3: grup I | W3: grup II | X3: grup III | Z3: bns | AB3: Grupa A | AC3: pkt | AD3: 3p | AE3: 4p | AF3: 5p | AG3: % | AH3: grup I | AI3: grup II | AJ3: grup III | AL3: Grupa E | AM3: pkt | AN3: 3t | AO3: 4p | AP3: 5p | AQ3: % | AR3: grup I | AS3: grup II | AT3: grup III
B4: 1 | C4: {=_xlfn.SORTBY(AB4:AJ10,AC4:AC10,-1,AG4:AG10,-1,AJ4:AJ10,-1,AH4:AH10,-1,AI4:AI10,-1)} -> Dario | D4: 0 | E4: 0 | F4: 0 | G4: 0 | H4: 0 | I4: 0 | J4: 0 | K4: 0 | M4: 15 | O4: 1 | P4: {=_xlfn.SORTBY(AL4:AT10,AM4:AM10,-1,AQ4:AQ10,-1,AT4:AT10,-1,AR4:AR10,-1,AS4:AS10,-1)} -> Talvik | Q4: 0 | R4: 0 | S4: 0 | T4: 0 | U4: 0 | V4: 0 | W4: 0 | X4: 0 | Z4: 15 | AB4: ='r1'!B5 -> Dario | AC4: =SUM(AH4:AJ4) -> 0 | AD4: ='r1'!AB5 -> 0 | AE4: ='r1'!AC5 -> 0 | AF4: ='r1'!AD5 -> 0 | AG4: =SUM(AD4:AF4)/$Z$1 -> 0 | AH4: ='r1'!AA5 -> 0 | AL4: ='r1'!B33 -> Talvik | AM4: =SUM(AR4:AT4) -> 0 | AN4: ='r1'!AB33 -> 0 | AO4: ='r1'!AC33 -> 0 | AP4: ='r1'!AD33 -> 0 | AQ4: =SUM(AN4:AP4)/$Z$1 -> 0 | AR4: ='r1'!AA33 -> 0
B5: 2 | C5: Wojtek | D5: 0 | E5: 0 | F5: 0 | G5: 0 | H5: 0 | I5: 0 | J5: 0 | K5: 0 | M5: 10 | O5: 2 | P5: Rafał | Q5: 0 | R5: 0 | S5: 0 | T5: 0 | U5: 0 | V5: 0 | W5: 0 | X5: 0 | Z5: 10 | AB5: ='r1'!B6 -> Wojtek | AC5: =SUM(AH5:AJ5) -> 0 | AD5: ='r1'!AB6 -> 0 | AE5: ='r1'!AC6 -> 0 | AF5: ='r1'!AD6 -> 0 | AG5: =SUM(AD5:AF5)/$Z$1 -> 0 | AH5: ='r1'!AA6 -> 0 | AL5: ='r1'!B34 -> Rafał | AM5: =SUM(AR5:AT5) -> 0 | AN5: ='r1'!AB34 -> 0 | AO5: ='r1'!AC34 -> 0 | AP5: ='r1'!AD34 -> 0 | AQ5: =SUM(AN5:AP5)/$Z$1 -> 0 | AR5: ='r1'!AA34 -> 0
B6: 3 | C6: KamUla | D6: 0 | E6: 0 | F6: 0 | G6: 0 | H6: 0 | I6: 0 | J6: 0 | K6: 0 | M6: 5 | O6: 3 | P6: MarekS | Q6: 0 | R6: 0 | S6: 0 | T6: 0 | U6: 0 | V6: 0 | W6: 0 | X6: 0 | Z6: 5 | AB6: ='r1'!B7 -> KamUla | AC6: =SUM(AH6:AJ6) -> 0 | AD6: ='r1'!AB7 -> 0 | AE6: ='r1'!AC7 -> 0 | AF6: ='r1'!AD7 -> 0 | AG6: =SUM(AD6:AF6)/$Z$1 -> 0 | AH6: ='r1'!AA7 -> 0 | AL6: ='r1'!B35 -> MarekS | AM6: =SUM(AR6:AT6) -> 0 | AN6: ='r1'!AB35 -> 0 | AO6: ='r1'!AC35 -> 0 | AP6: ='r1'!AD35 -> 0 | AQ6: =SUM(AN6:AP6)/$Z$1 -> 0 | AR6: ='r1'!AA35 -> 0
B7: 4 | C7: MagdaS | D7: 0 | E7: 0 | F7: 0 | G7: 0 | H7: 0 | I7: 0 | J7: 0 | K7: 0 | M7: =IF(B3=$D$44,4,"") | O7: 4 | P7: Karolina | Q7: 0 | R7: 0 | S7: 0 | T7: 0 | U7: 0 | V7: 0 | W7: 0 | X7: 0 | Z7: =IF(O3=$D$44,4,"") | AB7: ='r1'!B8 -> MagdaS | AC7: =SUM(AH7:AJ7) -> 0 | AD7: ='r1'!AB8 -> 0 | AE7: ='r1'!AC8 -> 0 | AF7: ='r1'!AD8 -> 0 | AG7: =SUM(AD7:AF7)/$Z$1 -> 0 | AH7: ='r1'!AA8 -> 0 | AL7: ='r1'!B36 -> Karolina | AM7: =SUM(AR7:AT7) -> 0 | AN7: ='r1'!AB36 -> 0 | AO7: ='r1'!AC36 -> 0 | AP7: ='r1'!AD36 -> 0 | AQ7: =SUM(AN7:AP7)/$Z$1 -> 0 | AR7: ='r1'!AA36 -> 0
B8: 5 | C8: KasiaJ | D8: 0 | E8: 0 | F8: 0 | G8: 0 | H8: 0 | I8: 0 | J8: 0 | K8: 0 | M8: =IF(B3=$D$44,3,"") | O8: 5 | P8: AndrzejO | Q8: 0 | R8: 0 | S8: 0 | T8: 0 | U8: 0 | V8: 0 | W8: 0 | X8: 0 | Z8: =IF(O3=$D$44,3,"") | AB8: ='r1'!B9 -> KasiaJ | AC8: =SUM(AH8:AJ8) -> 0 | AD8: ='r1'!AB9 -> 0 | AE8: ='r1'!AC9 -> 0 | AF8: ='r1'!AD9 -> 0 | AG8: =SUM(AD8:AF8)/$Z$1 -> 0 | AH8: ='r1'!AA9 -> 0 | AL8: ='r1'!B37 -> AndrzejO | AM8: =SUM(AR8:AT8) -> 0 | AN8: ='r1'!AB37 -> 0 | AO8: ='r1'!AC37 -> 0 | AP8: ='r1'!AD37 -> 0 | AQ8: =SUM(AN8:AP8)/$Z$1 -> 0 | AR8: ='r1'!AA37 -> 0
B9: 6 | C9: KrystianM | D9: 0 | E9: 0 | F9: 0 | G9: 0 | H9: 0 | I9: 0 | J9: 0 | K9: 0 | M9: =IF(B3=$D$44,2,"") | O9: 6 | P9: PiotreM | Q9: 0 | R9: 0 | S9: 0 | T9: 0 | U9: 0 | V9: 0 | W9: 0 | X9: 0 | Z9: =IF(O3=$D$44,2,"") | AB9: ='r1'!B10 -> KrystianM | AC9: =SUM(AH9:AJ9) -> 0 | AD9: ='r1'!AB10 -> 0 | AE9: ='r1'!AC10 -> 0 | AF9: ='r1'!AD10 -> 0 | AG9: =SUM(AD9:AF9)/$Z$1 -> 0 | AH9: ='r1'!AA10 -> 0 | AL9: ='r1'!B38 -> PiotreM | AM9: =SUM(AR9:AT9) -> 0 | AN9: ='r1'!AB38 -> 0 | AO9: ='r1'!AC38 -> 0 | AP9: ='r1'!AD38 -> 0 | AQ9: =SUM(AN9:AP9)/$Z$1 -> 0 | AR9: ='r1'!AA38 -> 0
B10: 7 | C10: PiotreG | D10: 0 | E10: 0 | F10: 0 | G10: 0 | H10: 0 | I10: 0 | J10: 0 | K10: 0 | M10: =IF(B3=$D$44,1,"") | O10: 7 | P10: DarekJell | Q10: 0 | R10: 0 | S10: 0 | T10: 0 | U10: 0 | V10: 0 | W10: 0 | X10: 0 | Z10: =IF(O3=$D$44,1,"") | AB10: ='r1'!B11 -> PiotreG | AC10: =SUM(AH10:AJ10) -> 0 | AD10: ='r1'!AB11 -> 0 | AE10: ='r1'!AC11 -> 0 | AF10: ='r1'!AD11 -> 0 | AG10: =SUM(AD10:AF10)/$Z$1 -> 0 | AH10: ='r1'!AA11 -> 0 | AL10: ='r1'!B39 -> DarekJell | AM10: =SUM(AR10:AT10) -> 0 | AN10: ='r1'!AB39 -> 0 | AO10: ='r1'!AC39 -> 0 | AP10: ='r1'!AD39 -> 0 | AQ10: =SUM(AN10:AP10)/$Z$1 -> 0 | AR10: ='r1'!AA39 -> 0
B12: =SUM(D13:D19) -> 0 | C12: Grupa B | D12: pkt | E12: 3p | F12: 4p | G12: 5p | H12: % | I12: grup I | J12: grup II | K12: grup III | M12: bns | O12: =SUM(Q13:Q19) -> 0 | P12: Grupa A | Q12: pkt | R12: 3p | S12: 4p | T12: 5p | U12: % | V12: grup I | W12: grup II | X12: grup III | Z12: bns | AB12: Grupa B | AC12: pkt | AD12: 3p | AE12: 4p | AF12: 5p | AG12: % | AH12: grup I | AI12: grup II | AJ12: grup III | AL12: Grupa F | AM12: pkt | AN12: 3t | AO12: 4p | AP12: 5p | AQ12: % | AR12: grup I | AS12: grup II | AT12: grup III
B13: 1 | C13: {=_xlfn.SORTBY(AB13:AJ19,AC13:AC19,-1,AG13:AG19,-1,AJ13:AJ19,-1,AH13:AH19,-1,AI13:AI19,-1)} -> Prozped | D13: 0 | E13: 0 | F13: 0 | G13: 0 | H13: 0 | I13: 0 | J13: 0 | K13: 0 | M13: 15 | O13: 1 | P13: {=_xlfn.SORTBY(AL13:AT19,AM13:AM19,-1,AQ13:AQ19,-1,AT13:AT19,-1,AR13:AR19,-1,AS13:AS19,-1)} -> Maciej | Q13: 0 | R13: 0 | S13: 0 | T13: 0 | U13: 0 | V13: 0 | W13: 0 | X13: 0 | Z13: 15 | AB13: ='r1'!B12 -> Prozped | AC13: =SUM(AH13:AJ13) -> 0 | AD13: ='r1'!AB12 -> 0 | AE13: ='r1'!AC12 -> 0 | AF13: ='r1'!AD12 -> 0 | AG13: =SUM(AD13:AF13)/$Z$1 -> 0 | AH13: ='r1'!AA12 -> 0 | AL13: ='r1'!B40 -> Maciej | AM13: =SUM(AR13:AT13) -> 0 | AN13: ='r1'!AB40 -> 0 | AO13: ='r1'!AC40 -> 0 | AP13: ='r1'!AD40 -> 0 | AQ13: =SUM(AN13:AP13)/$Z$1 -> 0 | AR13: ='r1'!AA40 -> 0
B14: 2 | C14: Artur | D14: 0 | E14: 0 | F14: 0 | G14: 0 | H14: 0 | I14: 0 | J14: 0 | K14: 0 | M14: 10 | O14: 2 | P14: KSZ | Q14: 0 | R14: 0 | S14: 0 | T14: 0 | U14: 0 | V14: 0 | W14: 0 | X14: 0 | Z14: 10 | AB14: ='r1'!B13 -> Artur | AC14: =SUM(AH14:AJ14) -> 0 | AD14: ='r1'!AB13 -> 0 | AE14: ='r1'!AC13 -> 0 | AF14: ='r1'!AD13 -> 0 | AG14: =SUM(AD14:AF14)/$Z$1 -> 0 | AH14: ='r1'!AA13 -> 0 | AL14: ='r1'!B41 -> KSZ | AM14: =SUM(AR14:AT14) -> 0 | AN14: ='r1'!AB41 -> 0 | AO14: ='r1'!AC41 -> 0 | AP14: ='r1'!AD41 -> 0 | AQ14: =SUM(AN14:AP14)/$Z$1 -> 0 | AR14: ='r1'!AA41 -> 0
B15: 3 | C15: Sokółka | D15: 0 | E15: 0 | F15: 0 | G15: 0 | H15: 0 | I15: 0 | J15: 0 | K15: 0 | M15: 5 | O15: 3 | P15: MarekP | Q15: 0 | R15: 0 | S15: 0 | T15: 0 | U15: 0 | V15: 0 | W15: 0 | X15: 0 | Z15: 5 | AB15: ='r1'!B14 -> Sokółka | AC15: =SUM(AH15:AJ15) -> 0 | AD15: ='r1'!AB14 -> 0 | AE15: ='r1'!AC14 -> 0 | AF15: ='r1'!AD14 -> 0 | AG15: =SUM(AD15:AF15)/$Z$1 -> 0 | AH15: ='r1'!AA14 -> 0 | AL15: ='r1'!B42 -> MarekP | AM15: =SUM(AR15:AT15) -> 0 | AN15: ='r1'!AB42 -> 0 | AO15: ='r1'!AC42 -> 0 | AP15: ='r1'!AD42 -> 0 | AQ15: =SUM(AN15:AP15)/$Z$1 -> 0 | AR15: ='r1'!AA42 -> 0
B16: 4 | C16: KasiaK | D16: 0 | E16: 0 | F16: 0 | G16: 0 | H16: 0 | I16: 0 | J16: 0 | K16: 0 | M16: =IF(B12=$D$44,4,"") | O16: 4 | P16: KleoPatra | Q16: 0 | R16: 0 | S16: 0 | T16: 0 | U16: 0 | V16: 0 | W16: 0 | X16: 0 | Z16: =IF(O12=$D$44,4,"") | AB16: ='r1'!B15 -> KasiaK | AC16: =SUM(AH16:AJ16) -> 0 | AD16: ='r1'!AB15 -> 0 | AE16: ='r1'!AC15 -> 0 | AF16: ='r1'!AD15 -> 0 | AG16: =SUM(AD16:AF16)/$Z$1 -> 0 | AH16: ='r1'!AA15 -> 0 | AL16: ='r1'!B43 -> KleoPatra | AM16: =SUM(AR16:AT16) -> 0 | AN16: ='r1'!AB43 -> 0 | AO16: ='r1'!AC43 -> 0 | AP16: ='r1'!AD43 -> 0 | AQ16: =SUM(AN16:AP16)/$Z$1 -> 0 | AR16: ='r1'!AA43 -> 0
B17: 5 | C17: Seweryn | D17: 0 | E17: 0 | F17: 0 | G17: 0 | H17: 0 | I17: 0 | J17: 0 | K17: 0 | M17: =IF(B12=$D$44,3,"") | O17: 5 | P17: MichałeK | Q17: 0 | R17: 0 | S17: 0 | T17: 0 | U17: 0 | V17: 0 | W17: 0 | X17: 0 | Z17: =IF(O12=$D$44,3,"") | AB17: ='r1'!B16 -> Seweryn | AC17: =SUM(AH17:AJ17) -> 0 | AD17: ='r1'!AB16 -> 0 | AE17: ='r1'!AC16 -> 0 | AF17: ='r1'!AD16 -> 0 | AG17: =SUM(AD17:AF17)/$Z$1 -> 0 | AH17: ='r1'!AA16 -> 0 | AL17: ='r1'!B44 -> MichałeK | AM17: =SUM(AR17:AT17) -> 0 | AN17: ='r1'!AB44 -> 0 | AO17: ='r1'!AC44 -> 0 | AP17: ='r1'!AD44 -> 0 | AQ17: =SUM(AN17:AP17)/$Z$1 -> 0 | AR17: ='r1'!AA44 -> 0
B18: 6 | C18: DarekL | D18: 0 | E18: 0 | F18: 0 | G18: 0 | H18: 0 | I18: 0 | J18: 0 | K18: 0 | M18: =IF(B12=$D$44,2,"") | O18: 6 | P18: Witek | Q18: 0 | R18: 0 | S18: 0 | T18: 0 | U18: 0 | V18: 0 | W18: 0 | X18: 0 | Z18: =IF(O12=$D$44,2,"") | AB18: ='r1'!B17 -> DarekL | AC18: =SUM(AH18:AJ18) -> 0 | AD18: ='r1'!AB17 -> 0 | AE18: ='r1'!AC17 -> 0 | AF18: ='r1'!AD17 -> 0 | AG18: =SUM(AD18:AF18)/$Z$1 -> 0 | AH18: ='r1'!AA17 -> 0 | AL18: ='r1'!B45 -> Witek | AM18: =SUM(AR18:AT18) -> 0 | AN18: ='r1'!AB45 -> 0 | AO18: ='r1'!AC45 -> 0 | AP18: ='r1'!AD45 -> 0 | AQ18: =SUM(AN18:AP18)/$Z$1 -> 0 | AR18: ='r1'!AA45 -> 0
B19: 7 | C19: KrzysztoW | D19: 0 | E19: 0 | F19: 0 | G19: 0 | H19: 0 | I19: 0 | J19: 0 | K19: 0 | M19: =IF(B12=$D$44,1,"") | O19: 7 | P19: RobertLat | Q19: 0 | R19: 0 | S19: 0 | T19: 0 | U19: 0 | V19: 0 | W19: 0 | X19: 0 | Z19: =IF(O12=$D$44,1,"") | AB19: ='r1'!B18 -> KrzysztoW | AC19: =SUM(AH19:AJ19) -> 0 | AD19: ='r1'!AB18 -> 0 | AE19: ='r1'!AC18 -> 0 | AF19: ='r1'!AD18 -> 0 | AG19: =SUM(AD19:AF19)/$Z$1 -> 0 | AH19: ='r1'!AA18 -> 0 | AL19: ='r1'!B46 -> RobertLat | AM19: =SUM(AR19:AT19) -> 0 | AN19: ='r1'!AB46 -> 0 | AO19: ='r1'!AC46 -> 0 | AP19: ='r1'!AD46 -> 0 | AQ19: =SUM(AN19:AP19)/$Z$1 -> 0 | AR19: ='r1'!AA46 -> 0
B21: =SUM(D22:D28) -> 0 | C21: Grupa C | D21: pkt | E21: 3p | F21: 4p | G21: 5p | H21: % | I21: grup I | J21: grup II | K21: grup III | M21: bns | O21: =SUM(Q22:Q28) -> 0 | P21: Grupa A | Q21: pkt | R21: 3p | S21: 4p | T21: 5p | U21: % | V21: grup I | W21: grup II | X21: grup III | Z21: bns | AB21: Grupa C | AC21: pkt | AD21: 3p | AE21: 4p | AF21: 5p | AG21: % | AH21: grup I | AI21: grup II | AJ21: grup III | AL21: Grupa G | AM21: pkt | AN21: 3t | AO21: 4p | AP21: 5p | AQ21: % | AR21: grup I | AS21: grup II | AT21: grup III
B22: 1 | C22: {=_xlfn.SORTBY(AB22:AJ28,AC22:AC28,-1,AG22:AG28,-1,AJ22:AJ28,-1,AH22:AH28,-1,AI22:AI28,-1)} -> Magiera | D22: 0 | E22: 0 | F22: 0 | G22: 0 | H22: 0 | I22: 0 | J22: 0 | K22: 0 | M22: 15 | O22: 1 | P22: {=_xlfn.SORTBY(AL22:AT28,AM22:AM28,-1,AQ22:AQ28,-1,AT22:AT28,-1,AR22:AR28,-1,AS22:AS28,-1)} -> DeDe | Q22: 0 | R22: 0 | S22: 0 | T22: 0 | U22: 0 | V22: 0 | W22: 0 | X22: 0 | Z22: 15 | AB22: ='r1'!B19 -> Magiera | AC22: =SUM(AH22:AJ22) -> 0 | AD22: ='r1'!AB19 -> 0 | AE22: ='r1'!AC19 -> 0 | AF22: ='r1'!AD19 -> 0 | AG22: =SUM(AD22:AF22)/$Z$1 -> 0 | AH22: ='r1'!AA19 -> 0 | AL22: ='r1'!B47 -> DeDe | AM22: =SUM(AR22:AT22) -> 0 | AN22: ='r1'!AB47 -> 0 | AO22: ='r1'!AC47 -> 0 | AP22: ='r1'!AD47 -> 0 | AQ22: =SUM(AN22:AP22)/$Z$1 -> 0 | AR22: ='r1'!AA47 -> 0
B23: 2 | C23: Henryk | D23: 0 | E23: 0 | F23: 0 | G23: 0 | H23: 0 | I23: 0 | J23: 0 | K23: 0 | M23: 10 | O23: 2 | P23: Cypryjka | Q23: 0 | R23: 0 | S23: 0 | T23: 0 | U23: 0 | V23: 0 | W23: 0 | X23: 0 | Z23: 10 | AB23: ='r1'!B20 -> Henryk | AC23: =SUM(AH23:AJ23) -> 0 | AD23: ='r1'!AB20 -> 0 | AE23: ='r1'!AC20 -> 0 | AF23: ='r1'!AD20 -> 0 | AG23: =SUM(AD23:AF23)/$Z$1 -> 0 | AH23: ='r1'!AA20 -> 0 | AL23: ='r1'!B48 -> Cypryjka | AM23: =SUM(AR23:AT23) -> 0 | AN23: ='r1'!AB48 -> 0 | AO23: ='r1'!AC48 -> 0 | AP23: ='r1'!AD48 -> 0 | AQ23: =SUM(AN23:AP23)/$Z$1 -> 0 | AR23: ='r1'!AA48 -> 0
B24: 3 | C24: PPP | D24: 0 | E24: 0 | F24: 0 | G24: 0 | H24: 0 | I24: 0 | J24: 0 | K24: 0 | M24: 5 | O24: 3 | P24: Tabus | Q24: 0 | R24: 0 | S24: 0 | T24: 0 | U24: 0 | V24: 0 | W24: 0 | X24: 0 | Z24: 5 | AB24: ='r1'!B21 -> PPP | AC24: =SUM(AH24:AJ24) -> 0 | AD24: ='r1'!AB21 -> 0 | AE24: ='r1'!AC21 -> 0 | AF24: ='r1'!AD21 -> 0 | AG24: =SUM(AD24:AF24)/$Z$1 -> 0 | AH24: ='r1'!AA21 -> 0 | AL24: ='r1'!B49 -> Tabus | AM24: =SUM(AR24:AT24) -> 0 | AN24: ='r1'!AB49 -> 0 | AO24: ='r1'!AC49 -> 0 | AP24: ='r1'!AD49 -> 0 | AQ24: =SUM(AN24:AP24)/$Z$1 -> 0 | AR24: ='r1'!AA49 -> 0
B25: 4 | C25: Żaklina | D25: 0 | E25: 0 | F25: 0 | G25: 0 | H25: 0 | I25: 0 | J25: 0 | K25: 0 | M25: =IF(B21=$D$44,4,"") | O25: 4 | P25: AniaS | Q25: 0 | R25: 0 | S25: 0 | T25: 0 | U25: 0 | V25: 0 | W25: 0 | X25: 0 | Z25: =IF(O21=$D$44,4,"") | AB25: ='r1'!B22 -> Żaklina | AC25: =SUM(AH25:AJ25) -> 0 | AD25: ='r1'!AB22 -> 0 | AE25: ='r1'!AC22 -> 0 | AF25: ='r1'!AD22 -> 0 | AG25: =SUM(AD25:AF25)/$Z$1 -> 0 | AH25: ='r1'!AA22 -> 0 | AL25: ='r1'!B50 -> AniaS | AM25: =SUM(AR25:AT25) -> 0 | AN25: ='r1'!AB50 -> 0 | AO25: ='r1'!AC50 -> 0 | AP25: ='r1'!AD50 -> 0 | AQ25: =SUM(AN25:AP25)/$Z$1 -> 0 | AR25: ='r1'!AA50 -> 0
B26: 5 | C26: Cezary | D26: 0 | E26: 0 | F26: 0 | G26: 0 | H26: 0 | I26: 0 | J26: 0 | K26: 0 | M26: =IF(B21=$D$44,3,"") | O26: 5 | P26: Pimozid | Q26: 0 | R26: 0 | S26: 0 | T26: 0 | U26: 0 | V26: 0 | W26: 0 | X26: 0 | Z26: =IF(O21=$D$44,3,"") | AB26: ='r1'!B23 -> Cezary | AC26: =SUM(AH26:AJ26) -> 0 | AD26: ='r1'!AB23 -> 0 | AE26: ='r1'!AC23 -> 0 | AF26: ='r1'!AD23 -> 0 | AG26: =SUM(AD26:AF26)/$Z$1 -> 0 | AH26: ='r1'!AA23 -> 0 | AL26: ='r1'!B51 -> Pimozid | AM26: =SUM(AR26:AT26) -> 0 | AN26: ='r1'!AB51 -> 0 | AO26: ='r1'!AC51 -> 0 | AP26: ='r1'!AD51 -> 0 | AQ26: =SUM(AN26:AP26)/$Z$1 -> 0 | AR26: ='r1'!AA51 -> 0
B27: 6 | C27: Dziobak | D27: 0 | E27: 0 | F27: 0 | G27: 0 | H27: 0 | I27: 0 | J27: 0 | K27: 0 | M27: =IF(B21=$D$44,2,"") | O27: 6 | P27: KrzysztoWś | Q27: 0 | R27: 0 | S27: 0 | T27: 0 | U27: 0 | V27: 0 | W27: 0 | X27: 0 | Z27: =IF(O21=$D$44,2,"") | AB27: ='r1'!B24 -> Dziobak | AC27: =SUM(AH27:AJ27) -> 0 | AD27: ='r1'!AB24 -> 0 | AE27: ='r1'!AC24 -> 0 | AF27: ='r1'!AD24 -> 0 | AG27: =SUM(AD27:AF27)/$Z$1 -> 0 | AH27: ='r1'!AA24 -> 0 | AL27: ='r1'!B52 -> KrzysztoWś | AM27: =SUM(AR27:AT27) -> 0 | AN27: ='r1'!AB52 -> 0 | AO27: ='r1'!AC52 -> 0 | AP27: ='r1'!AD52 -> 0 | AQ27: =SUM(AN27:AP27)/$Z$1 -> 0 | AR27: ='r1'!AA52 -> 0
B28: 7 | C28: MateuszKn | D28: 0 | E28: 0 | F28: 0 | G28: 0 | H28: 0 | I28: 0 | J28: 0 | K28: 0 | M28: =IF(B21=$D$44,1,"") | O28: 7 | P28: Ruslan | Q28: 0 | R28: 0 | S28: 0 | T28: 0 | U28: 0 | V28: 0 | W28: 0 | X28: 0 | Z28: =IF(O21=$D$44,1,"") | AB28: ='r1'!B25 -> MateuszKn | AC28: =SUM(AH28:AJ28) -> 0 | AD28: ='r1'!AB25 -> 0 | AE28: ='r1'!AC25 -> 0 | AF28: ='r1'!AD25 -> 0 | AG28: =SUM(AD28:AF28)/$Z$1 -> 0 | AH28: ='r1'!AA25 -> 0 | AL28: ='r1'!B53 -> Ruslan | AM28: =SUM(AR28:AT28) -> 0 | AN28: ='r1'!AB53 -> 0 | AO28: ='r1'!AC53 -> 0 | AP28: ='r1'!AD53 -> 0 | AQ28: =SUM(AN28:AP28)/$Z$1 -> 0 | AR28: ='r1'!AA53 -> 0
B30: =SUM(D31:D37) -> 0 | C30: Grupa D | D30: pkt | E30: 3p | F30: 4p | G30: 5p | H30: % | I30: grup I | J30: grup II | K30: grup III | M30: bns | O30: =SUM(Q31:Q37) -> 0 | P30: Grupa A | Q30: pkt | R30: 3p | S30: 4p | T30: 5p | U30: % | V30: grup I | W30: grup II | X30: grup III | Z30: bns | AB30: Grupa D | AC30: pkt | AD30: 3t | AE30: 4p | AF30: 5p | AG30: % | AH30: grup I | AI30: grup II | AJ30: grup III | AL30: Grupa H | AM30: pkt | AN30: 3t | AO30: 4p | AP30: 5p | AQ30: % | AR30: grup I | AS30: grup II | AT30: grup III
B31: 1 | C31: {=_xlfn.SORTBY(AB31:AJ37,AC31:AC37,-1,AG31:AG37,-1,AJ31:AJ37,-1,AH31:AH37,-1,AI31:AI37,-1)} -> Przemek | D31: 0 | E31: 0 | F31: 0 | G31: 0 | H31: 0 | I31: 0 | J31: 0 | K31: 0 | M31: 15 | O31: 1 | P31: {=_xlfn.SORTBY(AL31:AT37,AM31:AM37,-1,AQ31:AQ37,-1,AT31:AT37,-1,AR31:AR37,-1,AS31:AS37,-1)} -> PiotreK | Q31: 0 | R31: 0 | S31: 0 | T31: 0 | U31: 0 | V31: 0 | W31: 0 | X31: 0 | Z31: 15 | AB31: ='r1'!B26 -> Przemek | AC31: =SUM(AH31:AJ31) -> 0 | AD31: ='r1'!AB26 -> 0 | AE31: ='r1'!AC26 -> 0 | AF31: ='r1'!AD26 -> 0 | AG31: =SUM(AD31:AF31)/$Z$1 -> 0 | AH31: ='r1'!AA26 -> 0 | AL31: ='r1'!B54 -> PiotreK | AM31: =SUM(AR31:AT31) -> 0 | AN31: ='r1'!AB54 -> 0 | AO31: ='r1'!AC54 -> 0 | AP31: ='r1'!AD54 -> 0 | AQ31: =SUM(AN31:AP31)/$Z$1 -> 0 | AR31: ='r1'!AA54 -> 0
B32: 2 | C32: Borys | D32: 0 | E32: 0 | F32: 0 | G32: 0 | H32: 0 | I32: 0 | J32: 0 | K32: 0 | M32: 10 | O32: 2 | P32: KaBed | Q32: 0 | R32: 0 | S32: 0 | T32: 0 | U32: 0 | V32: 0 | W32: 0 | X32: 0 | Z32: 10 | AB32: ='r1'!B27 -> Borys | AC32: =SUM(AH32:AJ32) -> 0 | AD32: ='r1'!AB27 -> 0 | AE32: ='r1'!AC27 -> 0 | AF32: ='r1'!AD27 -> 0 | AG32: =SUM(AD32:AF32)/$Z$1 -> 0 | AH32: ='r1'!AA27 -> 0 | AL32: ='r1'!B55 -> KaBed | AM32: =SUM(AR32:AT32) -> 0 | AN32: ='r1'!AB55 -> 0 | AO32: ='r1'!AC55 -> 0 | AP32: ='r1'!AD55 -> 0 | AQ32: =SUM(AN32:AP32)/$Z$1 -> 0 | AR32: ='r1'!AA55 -> 0
B33: 3 | C33: Turbo-Ryżu | D33: 0 | E33: 0 | F33: 0 | G33: 0 | H33: 0 | I33: 0 | J33: 0 | K33: 0 | M33: 5 | O33: 3 | P33: Mirella | Q33: 0 | R33: 0 | S33: 0 | T33: 0 | U33: 0 | V33: 0 | W33: 0 | X33: 0 | Z33: 5 | AB33: ='r1'!B28 -> Turbo-Ryżu | AC33: =SUM(AH33:AJ33) -> 0 | AD33: ='r1'!AB28 -> 0 | AE33: ='r1'!AC28 -> 0 | AF33: ='r1'!AD28 -> 0 | AG33: =SUM(AD33:AF33)/$Z$1 -> 0 | AH33: ='r1'!AA28 -> 0 | AL33: ='r1'!B56 -> Mirella | AM33: =SUM(AR33:AT33) -> 0 | AN33: ='r1'!AB56 -> 0 | AO33: ='r1'!AC56 -> 0 | AP33: ='r1'!AD56 -> 0 | AQ33: =SUM(AN33:AP33)/$Z$1 -> 0 | AR33: ='r1'!AA56 -> 0
B34: 4 | C34: MagdaP | D34: 0 | E34: 0 | F34: 0 | G34: 0 | H34: 0 | I34: 0 | J34: 0 | K34: 0 | M34: =IF(B30=$D$44,4,"") | O34: 4 | P34: Maria | Q34: 0 | R34: 0 | S34: 0 | T34: 0 | U34: 0 | V34: 0 | W34: 0 | X34: 0 | Z34: =IF(O30=$D$44,4,"") | AB34: ='r1'!B29 -> MagdaP | AC34: =SUM(AH34:AJ34) -> 0 | AD34: ='r1'!AB29 -> 0 | AE34: ='r1'!AC29 -> 0 | AF34: ='r1'!AD29 -> 0 | AG34: =SUM(AD34:AF34)/$Z$1 -> 0 | AH34: ='r1'!AA29 -> 0 | AL34: ='r1'!B57 -> Maria | AM34: =SUM(AR34:AT34) -> 0 | AN34: ='r1'!AB57 -> 0 | AO34: ='r1'!AC57 -> 0 | AP34: ='r1'!AD57 -> 0 | AQ34: =SUM(AN34:AP34)/$Z$1 -> 0 | AR34: ='r1'!AA57 -> 0
B35: 5 | C35: Małgorzata | D35: 0 | E35: 0 | F35: 0 | G35: 0 | H35: 0 | I35: 0 | J35: 0 | K35: 0 | M35: =IF(B30=$D$44,3,"") | O35: 5 | P35: Sławek | Q35: 0 | R35: 0 | S35: 0 | T35: 0 | U35: 0 | V35: 0 | W35: 0 | X35: 0 | Z35: =IF(O30=$D$44,3,"") | AB35: ='r1'!B30 -> Małgorzata | AC35: =SUM(AH35:AJ35) -> 0 | AD35: ='r1'!AB30 -> 0 | AE35: ='r1'!AC30 -> 0 | AF35: ='r1'!AD30 -> 0 | AG35: =SUM(AD35:AF35)/$Z$1 -> 0 | AH35: ='r1'!AA30 -> 0 | AL35: ='r1'!B58 -> Sławek | AM35: =SUM(AR35:AT35) -> 0 | AN35: ='r1'!AB58 -> 0 | AO35: ='r1'!AC58 -> 0 | AP35: ='r1'!AD58 -> 0 | AQ35: =SUM(AN35:AP35)/$Z$1 -> 0 | AR35: ='r1'!AA58 -> 0
B36: 6 | C36: KamilF | D36: 0 | E36: 0 | F36: 0 | G36: 0 | H36: 0 | I36: 0 | J36: 0 | K36: 0 | M36: =IF(B30=$D$44,2,"") | O36: 6 | P36: PawełSt | Q36: 0 | R36: 0 | S36: 0 | T36: 0 | U36: 0 | V36: 0 | W36: 0 | X36: 0 | Z36: =IF(O30=$D$44,2,"") | AB36: ='r1'!B31 -> KamilF | AC36: =SUM(AH36:AJ36) -> 0 | AD36: ='r1'!AB31 -> 0 | AE36: ='r1'!AC31 -> 0 | AF36: ='r1'!AD31 -> 0 | AG36: =SUM(AD36:AF36)/$Z$1 -> 0 | AH36: ='r1'!AA31 -> 0 | AL36: ='r1'!B59 -> PawełSt | AM36: =SUM(AR36:AT36) -> 0 | AN36: ='r1'!AB59 -> 0 | AO36: ='r1'!AC59 -> 0 | AP36: ='r1'!AD59 -> 0 | AQ36: =SUM(AN36:AP36)/$Z$1 -> 0 | AR36: ='r1'!AA59 -> 0
B37: 7 | C37: MichałCz | D37: 0 | E37: 0 | F37: 0 | G37: 0 | H37: 0 | I37: 0 | J37: 0 | K37: 0 | M37: =IF(B30=$D$44,1,"") | O37: 7 | P37: KrzysztofeR | Q37: 0 | R37: 0 | S37: 0 | T37: 0 | U37: 0 | V37: 0 | W37: 0 | X37: 0 | Z37: =IF(O30=$D$44,1,"") | AB37: ='r1'!B32 -> MichałCz | AC37: =SUM(AH37:AJ37) -> 0 | AD37: ='r1'!AB32 -> 0 | AE37: ='r1'!AC32 -> 0 | AF37: ='r1'!AD32 -> 0 | AG37: =SUM(AD37:AF37)/$Z$1 -> 0 | AH37: ='r1'!AA32 -> 0 | AL37: ='r1'!B60 -> KrzysztofeR | AM37: =SUM(AR37:AT37) -> 0 | AN37: ='r1'!AB60 -> 0 | AO37: ='r1'!AC60 -> 0 | AP37: ='r1'!AD60 -> 0 | AQ37: =SUM(AN37:AP37)/$Z$1 -> 0 | AR37: ='r1'!AA60 -> 0
C40: max grup I | D40: =MAX(I4:I37,V4:V37) -> 0
C41: max grup II
C42: max grup III
C44: grupa ABC… | D44: =MAX(B3:B37,O3:O37) -> 7

Sheet stat
B2: Gracz dnia | D2: pkt | F2: Trafienia za 5 pkt | H2: ile x | J2: Skuteczność | L2: % | N2: Forma (5 meczów) | P2: pkt | S2: Gracz dnia | T2: pkt | V2: trafienia za 5 pkt | Y2: skutecznosc | AB2: Forma
B3: 1 | C3: {=_xlfn.SORTBY(S3:T58,T3:T58,-1)} -> Dario | F3: 1 | G3: {=_xlfn.SORTBY(V3:W58,W3:W58,-1)} -> Dario | H3: 0 | J3: 1 | K3: {=_xlfn.SORTBY(Y3:Z58,Z3:Z58,-1)} -> Dario | L3: 0 | N3: 1 | O3: {=_xlfn.SORTBY(AB3:AC58,AC3:AC58,-1)} -> Dario | P3: #N/A | S3: ='day by day'!B6 -> Dario | T3: ='day by day'!C6 | V3: =tabela!Q3 -> Dario | W3: =tabela!U3+tabela!V3 -> 0 | Y3: =tabela!Q3 -> Dario | Z3: =tabela!W3 -> 0 | AB3: ='r1'!B5 -> Dario | AC3: ='r1'!AE5 -> #N/A
B4: 2 | C4: Wojtek | F4: 2 | G4: Wojtek | H4: 0 | J4: 2 | K4: Wojtek | L4: 0 | N4: 2 | O4: Wojtek | P4: #N/A | S4: ='day by day'!B7 -> Wojtek | T4: ='day by day'!C7 | V4: =tabela!Q4 -> Wojtek | W4: =tabela!U4+tabela!V4 -> 0 | Y4: =tabela!Q4 -> Wojtek | Z4: =tabela!W4 -> 0 | AB4: ='r1'!B6 -> Wojtek | AC4: ='r1'!AE6 -> #N/A
B5: 3 | C5: KamUla | F5: 3 | G5: KamUla | H5: 0 | J5: 3 | K5: KamUla | L5: 0 | N5: 3 | O5: KamUla | P5: #N/A | S5: ='day by day'!B8 -> KamUla | T5: ='day by day'!C8 | V5: =tabela!Q5 -> KamUla | W5: =tabela!U5+tabela!V5 -> 0 | Y5: =tabela!Q5 -> KamUla | Z5: =tabela!W5 -> 0 | AB5: ='r1'!B7 -> KamUla | AC5: ='r1'!AE7 -> #N/A
B6: 4 | C6: MagdaS | F6: 4 | G6: MagdaS | H6: 0 | J6: 4 | K6: MagdaS | L6: 0 | N6: 4 | O6: MagdaS | P6: #N/A | S6: ='day by day'!B9 -> MagdaS | T6: ='day by day'!C9 | V6: =tabela!Q6 -> MagdaS | W6: =tabela!U6+tabela!V6 -> 0 | Y6: =tabela!Q6 -> MagdaS | Z6: =tabela!W6 -> 0 | AB6: ='r1'!B8 -> MagdaS | AC6: ='r1'!AE8 -> #N/A
B7: 5 | C7: KasiaJ | F7: 5 | G7: KasiaJ | H7: 0 | J7: 5 | K7: KasiaJ | L7: 0 | N7: 5 | O7: KasiaJ | P7: #N/A | S7: ='day by day'!B10 -> KasiaJ | T7: ='day by day'!C10 | V7: =tabela!Q7 -> KasiaJ | W7: =tabela!U7+tabela!V7 -> 0 | Y7: =tabela!Q7 -> KasiaJ | Z7: =tabela!W7 -> 0 | AB7: ='r1'!B9 -> KasiaJ | AC7: ='r1'!AE9 -> #N/A
B8: 6 | C8: KrystianM | F8: 6 | G8: KrystianM | H8: 0 | J8: 6 | K8: KrystianM | L8: 0 | N8: 6 | O8: KrystianM | P8: #N/A | S8: ='day by day'!B11 -> KrystianM | T8: ='day by day'!C11 | V8: =tabela!Q8 -> KrystianM | W8: =tabela!U8+tabela!V8 -> 0 | Y8: =tabela!Q8 -> KrystianM | Z8: =tabela!W8 -> 0 | AB8: ='r1'!B10 -> KrystianM | AC8: ='r1'!AE10 -> #N/A
B9: 7 | C9: PiotreG | F9: 7 | G9: PiotreG | H9: 0 | J9: 7 | K9: PiotreG | L9: 0 | N9: 7 | O9: PiotreG | P9: #N/A | S9: ='day by day'!B12 -> PiotreG | T9: ='day by day'!C12 | V9: =tabela!Q9 -> PiotreG | W9: =tabela!U9+tabela!V9 -> 0 | Y9: =tabela!Q9 -> PiotreG | Z9: =tabela!W9 -> 0 | AB9: ='r1'!B11 -> PiotreG | AC9: ='r1'!AE11 -> #N/A
B10: 8 | C10: Prozped | F10: 8 | G10: Prozped | H10: 0 | J10: 8 | K10: Prozped | L10: 0 | N10: 8 | O10: Prozped | P10: #N/A | S10: ='day by day'!B13 -> Prozped | T10: ='day by day'!C13 | V10: =tabela!Q10 -> Prozped | W10: =tabela!U10+tabela!V10 -> 0 | Y10: =tabela!Q10 -> Prozped | Z10: =tabela!W10 -> 0 | AB10: ='r1'!B12 -> Prozped | AC10: ='r1'!AE12 -> #N/A
B11: 9 | C11: Artur | F11: 9 | G11: Artur | H11: 0 | J11: 9 | K11: Artur | L11: 0 | N11: 9 | O11: Artur | P11: #N/A | S11: ='day by day'!B14 -> Artur | T11: ='day by day'!C14 | V11: =tabela!Q11 -> Artur | W11: =tabela!U11+tabela!V11 -> 0 | Y11: =tabela!Q11 -> Artur | Z11: =tabela!W11 -> 0 | AB11: ='r1'!B13 -> Artur | AC11: ='r1'!AE13 -> #N/A
B12: 10 | C12: Sokółka | F12: 10 | G12: Sokółka | H12: 0 | J12: 10 | K12: Sokółka | L12: 0 | N12: 10 | O12: Sokółka | P12: #N/A | S12: ='day by day'!B15 -> Sokółka | T12: ='day by day'!C15 | V12: =tabela!Q12 -> Sokółka | W12: =tabela!U12+tabela!V12 -> 0 | Y12: =tabela!Q12 -> Sokółka | Z12: =tabela!W12 -> 0 | AB12: ='r1'!B14 -> Sokółka | AC12: ='r1'!AE14 -> #N/A
B13: 11 | C13: KasiaK | F13: 11 | G13: KasiaK | H13: 0 | J13: 11 | K13: KasiaK | L13: 0 | N13: 11 | O13: KasiaK | P13: #N/A | S13: ='day by day'!B16 -> KasiaK | T13: ='day by day'!C16 | V13: =tabela!Q13 -> KasiaK | W13: =tabela!U13+tabela!V13 -> 0 | Y13: =tabela!Q13 -> KasiaK | Z13: =tabela!W13 -> 0 | AB13: ='r1'!B15 -> KasiaK | AC13: ='r1'!AE15 -> #N/A
B14: 12 | C14: Seweryn | F14: 12 | G14: Seweryn | H14: 0 | J14: 12 | K14: Seweryn | L14: 0 | N14: 12 | O14: Seweryn | P14: #N/A | S14: ='day by day'!B17 -> Seweryn | T14: ='day by day'!C17 | V14: =tabela!Q14 -> Seweryn | W14: =tabela!U14+tabela!V14 -> 0 | Y14: =tabela!Q14 -> Seweryn | Z14: =tabela!W14 -> 0 | AB14: ='r1'!B16 -> Seweryn | AC14: ='r1'!AE16 -> #N/A
B15: 13 | C15: DarekL | F15: 13 | G15: DarekL | H15: 0 | J15: 13 | K15: DarekL | L15: 0 | N15: 13 | O15: DarekL | P15: #N/A | S15: ='day by day'!B18 -> DarekL | T15: ='day by day'!C18 | V15: =tabela!Q15 -> DarekL | W15: =tabela!U15+tabela!V15 -> 0 | Y15: =tabela!Q15 -> DarekL | Z15: =tabela!W15 -> 0 | AB15: ='r1'!B17 -> DarekL | AC15: ='r1'!AE17 -> #N/A
... B58: 56 | C58: KrzysztofeR | F58: 56 | G58: KrzysztofeR | H58: 0 | J58: 56 | K58: KrzysztofeR | L58: 0 | N58: 56 | O58: KrzysztofeR | P58: #N/A | S58: ='day by day'!B61 -> KrzysztofeR | T58: ='day by day'!C61 | V58: =tabela!Q58 -> KrzysztofeR | W58: =tabela!U58+tabela!V58 -> 0 | Y58: =tabela!Q58 -> KrzysztofeR | Z58: =tabela!W58 -> 0 | AB58: ='r1'!B60 -> KrzysztofeR | AC58: ='r1'!AE60 -> #N/A

Sheet ...

Sheet tabela
B1: MŚ 2026 USA - MEKSYK - KANADA - Tabela Konkursu I-go | N1: ='r1'!AE2 -> 1
B2: lp | C2: uczestnik | D2: pkt | E2: 3p | F2: 4p | G2: 5p | H2: 6p | I2: % | J2: gr I | K2: gr II | L2: gr III | M2: bns | N2: puch | Q2: uczestnik | R2: pkt | S2: 3p | T2: 4p | U2: 5p | V2: 6p | W2: % | X2: gr I | Y2: gr II | Z2: gr III | AA2: bns | AB2: puch
B3: 1 | C3: {=_xlfn.SORTBY(Q3:AB58,R3:R58,-1,W3:W58,-1,AB3:AB58,-1,Z3:Z58,-1,Y3:Y58,-1,X3:X58,-1)} -> Dario | D3: 0 | E3: 0 | F3: 0 | G3: 0 | H3: 0 | I3: 0 | J3: 0 | K3: 0 | L3: 0 | M3: 0 | N3: 0 | Q3: Dario | R3: =SUM(X3:AB3) -> 0 | S3: ='r1'!AB5 -> 0 | T3: ='r1'!AC5 -> 0 | U3: ='r1'!AD5 -> 0 | W3: =SUM(S3:V3)/$N$1 -> 0 | X3: ='r1'!AA5 -> 0
B4: 2 | C4: Wojtek | D4: 0 | E4: 0 | F4: 0 | G4: 0 | H4: 0 | I4: 0 | J4: 0 | K4: 0 | L4: 0 | M4: 0 | N4: 0 | Q4: Wojtek | R4: =SUM(X4:AB4) -> 0 | S4: ='r1'!AB6 -> 0 | T4: ='r1'!AC6 -> 0 | U4: ='r1'!AD6 -> 0 | W4: =SUM(S4:V4)/$N$1 -> 0 | X4: ='r1'!AA6 -> 0
B5: 3 | C5: KamUla | D5: 0 | E5: 0 | F5: 0 | G5: 0 | H5: 0 | I5: 0 | J5: 0 | K5: 0 | L5: 0 | M5: 0 | N5: 0 | Q5: KamUla | R5: =SUM(X5:AB5) -> 0 | S5: ='r1'!AB7 -> 0 | T5: ='r1'!AC7 -> 0 | U5: ='r1'!AD7 -> 0 | W5: =SUM(S5:V5)/$N$1 -> 0 | X5: ='r1'!AA7 -> 0
B6: 4 | C6: MagdaS | D6: 0 | E6: 0 | F6: 0 | G6: 0 | H6: 0 | I6: 0 | J6: 0 | K6: 0 | L6: 0 | M6: 0 | N6: 0 | Q6: MagdaS | R6: =SUM(X6:AB6) -> 0 | S6: ='r1'!AB8 -> 0 | T6: ='r1'!AC8 -> 0 | U6: ='r1'!AD8 -> 0 | W6: =SUM(S6:V6)/$N$1 -> 0 | X6: ='r1'!AA8 -> 0
B7: 5 | C7: KasiaJ | D7: 0 | E7: 0 | F7: 0 | G7: 0 | H7: 0 | I7: 0 | J7: 0 | K7: 0 | L7: 0 | M7: 0 | N7: 0 | Q7: KasiaJ | R7: =SUM(X7:AB7) -> 0 | S7: ='r1'!AB9 -> 0 | T7: ='r1'!AC9 -> 0 | U7: ='r1'!AD9 -> 0 | W7: =SUM(S7:V7)/$N$1 -> 0 | X7: ='r1'!AA9 -> 0
B8: 6 | C8: KrystianM | D8: 0 | E8: 0 | F8: 0 | G8: 0 | H8: 0 | I8: 0 | J8: 0 | K8: 0 | L8: 0 | M8: 0 | N8: 0 | Q8: KrystianM | R8: =SUM(X8:AB8) -> 0 | S8: ='r1'!AB10 -> 0 | T8: ='r1'!AC10 -> 0 | U8: ='r1'!AD10 -> 0 | W8: =SUM(S8:V8)/$N$1 -> 0 | X8: ='r1'!AA10 -> 0
B9: 7 | C9: PiotreG | D9: 0 | E9: 0 | F9: 0 | G9: 0 | H9: 0 | I9: 0 | J9: 0 | K9: 0 | L9: 0 | M9: 0 | N9: 0 | Q9: PiotreG | R9: =SUM(X9:AB9) -> 0 | S9: ='r1'!AB11 -> 0 | T9: ='r1'!AC11 -> 0 | U9: ='r1'!AD11 -> 0 | W9: =SUM(S9:V9)/$N$1 -> 0 | X9: ='r1'!AA11 -> 0
B10: 8 | C10: Prozped | D10: 0 | E10: 0 | F10: 0 | G10: 0 | H10: 0 | I10: 0 | J10: 0 | K10: 0 | L10: 0 | M10: 0 | N10: 0 | Q10: Prozped | R10: =SUM(X10:AB10) -> 0 | S10: ='r1'!AB12 -> 0 | T10: ='r1'!AC12 -> 0 | U10: ='r1'!AD12 -> 0 | W10: =SUM(S10:V10)/$N$1 -> 0 | X10: ='r1'!AA12 -> 0
B11: 9 | C11: Artur | D11: 0 | E11: 0 | F11: 0 | G11: 0 | H11: 0 | I11: 0 | J11: 0 | K11: 0 | L11: 0 | M11: 0 | N11: 0 | Q11: Artur | R11: =SUM(X11:AB11) -> 0 | S11: ='r1'!AB13 -> 0 | T11: ='r1'!AC13 -> 0 | U11: ='r1'!AD13 -> 0 | W11: =SUM(S11:V11)/$N$1 -> 0 | X11: ='r1'!AA13 -> 0
B12: 10 | C12: Sokółka | D12: 0 | E12: 0 | F12: 0 | G12: 0 | H12: 0 | I12: 0 | J12: 0 | K12: 0 | L12: 0 | M12: 0 | N12: 0 | Q12: Sokółka | R12: =SUM(X12:AB12) -> 0 | S12: ='r1'!AB14 -> 0 | T12: ='r1'!AC14 -> 0 | U12: ='r1'!AD14 -> 0 | W12: =SUM(S12:V12)/$N$1 -> 0 | X12: ='r1'!AA14 -> 0
B13: 11 | C13: KasiaK | D13: 0 | E13: 0 | F13: 0 | G13: 0 | H13: 0 | I13: 0 | J13: 0 | K13: 0 | L13: 0 | M13: 0 | N13: 0 | Q13: KasiaK | R13: =SUM(X13:AB13) -> 0 | S13: ='r1'!AB15 -> 0 | T13: ='r1'!AC15 -> 0 | U13: ='r1'!AD15 -> 0 | W13: =SUM(S13:V13)/$N$1 -> 0 | X13: ='r1'!AA15 -> 0
B14: 12 | C14: Seweryn | D14: 0 | E14: 0 | F14: 0 | G14: 0 | H14: 0 | I14: 0 | J14: 0 | K14: 0 | L14: 0 | M14: 0 | N14: 0 | Q14: Seweryn | R14: =SUM(X14:AB14) -> 0 | S14: ='r1'!AB16 -> 0 | T14: ='r1'!AC16 -> 0 | U14: ='r1'!AD16 -> 0 | W14: =SUM(S14:V14)/$N$1 -> 0 | X14: ='r1'!AA16 -> 0
B15: 13 | C15: DarekL | D15: 0 | E15: 0 | F15: 0 | G15: 0 | H15: 0 | I15: 0 | J15: 0 | K15: 0 | L15: 0 | M15: 0 | N15: 0 | Q15: DarekL | R15: =SUM(X15:AB15) -> 0 | S15: ='r1'!AB17 -> 0 | T15: ='r1'!AC17 -> 0 | U15: ='r1'!AD17 -> 0 | W15: =SUM(S15:V15)/$N$1 -> 0 | X15: ='r1'!AA17 -> 0
... B58: 56 | C58: KrzysztofeR | D58: 0 | E58: 0 | F58: 0 | G58: 0 | H58: 0 | I58: 0 | J58: 0 | K58: 0 | L58: 0 | M58: 0 | N58: 0 | Q58: KrzysztofeR | R58: =SUM(X58:AB58) -> 0 | S58: ='r1'!AB60 -> 0 | T58: ='r1'!AC60 -> 0 | U58: ='r1'!AD60 -> 0 | W58: =SUM(S58:V58)/$N$1 -> 0 | X58: ='r1'!AA60 -> 0
J61: =MAX(J3:J58) -> 0 | K61: x | L61: x | N61: x

Sheet r1
B2: MŚ 2026 USA - MEKSYK - KANADA - punkty mecz po meczu - I runda, tura 1 | AE2: 1
C4: MEX-RSA | D4: KOR-CZE | E4: CAN-BIH | F4: USA-PAR | G4: QAT-SUI | H4: BRA-MOR | I4: HAI-SCO | J4: AUS-TUR | K4: GER-CUR | L4: HOL-JPN | M4: WKS-EQU | N4: SWE-TUN | O4: ESP-VRD | P4: BEL-EGY | Q4: KSA-URU | R4: IRN-NZL | S4: FRA-SEN | T4: IRQ-NOR | U4: ARG-ALG | V4: AUT-JRD | W4: POR-CNG | X4: ENG-CRO | Y4: GHA-PAN | Z4: UZB-COL | AA4: pkt | AB4: za 3 | AC4: za 4 | AD4: za 5 | AE4: forma
B5: Dario | C5: ='grup-1'!H6 | D5: ='grup-1'!H37 | E5: ='grup-1'!H68 | F5: ='grup-1'!H99 | G5: ='grup-1'!H130 | H5: ='grup-1'!H161 | I5: ='grup-1'!H192 | J5: ='grup-1'!H223 | K5: ='grup-1'!H254 | L5: ='grup-1'!H285 | M5: ='grup-1'!H316 | N5: ='grup-1'!H347 | O5: ='grup-1'!H379 | P5: ='grup-1'!H410 | Q5: ='grup-1'!H441 | R5: ='grup-1'!H472 | S5: ='grup-1'!H503 | T5: ='grup-1'!H534 | U5: ='grup-1'!H565 | V5: ='grup-1'!H596 | W5: ='grup-1'!H627 | X5: ='grup-1'!H658 | Y5: ='grup-1'!H689 | Z5: ='grup-1'!H720 | AA5: =AB5*3+AC5*4+AD5*5 -> 0 | AB5: =COUNTIF(C5:Z5,3) -> 0 | AC5: =COUNTIF(C5:Z5,4) -> 0 | AD5: =COUNTIF(C5:Z5,5) -> 0 | AE5: {=_xlfn.LET(_xlpm.z,C5:Z5,_xlpm.o,MATCH(2,1/(_xlpm.z<>"")),_xlpm.p,MAX(1,_xlpm.o-4),SUM(INDEX(_xlpm.z,_xlpm.p):INDEX(_xlpm.z,_xlpm.o)))} -> #N/A
B6: Wojtek | C6: ='grup-1'!H7 | D6: ='grup-1'!H38 | E6: ='grup-1'!H69 | F6: ='grup-1'!H100 | G6: ='grup-1'!H131 | H6: ='grup-1'!H162 | I6: ='grup-1'!H193 | J6: ='grup-1'!H224 | K6: ='grup-1'!H255 | L6: ='grup-1'!H286 | M6: ='grup-1'!H317 | N6: ='grup-1'!H348 | O6: ='grup-1'!H380 | P6: ='grup-1'!H411 | Q6: ='grup-1'!H442 | R6: ='grup-1'!H473 | S6: ='grup-1'!H504 | T6: ='grup-1'!H535 | U6: ='grup-1'!H566 | V6: ='grup-1'!H597 | W6: ='grup-1'!H628 | X6: ='grup-1'!H659 | Y6: ='grup-1'!H690 | Z6: ='grup-1'!H721 | AA6: =AB6*3+AC6*4+AD6*5 -> 0 | AB6: =COUNTIF(C6:Z6,3) -> 0 | AC6: =COUNTIF(C6:Z6,4) -> 0 | AD6: =COUNTIF(C6:Z6,5) -> 0 | AE6: {=_xlfn.LET(_xlpm.z,C6:Z6,_xlpm.o,MATCH(2,1/(_xlpm.z<>"")),_xlpm.p,MAX(1,_xlpm.o-4),SUM(INDEX(_xlpm.z,_xlpm.p):INDEX(_xlpm.z,_xlpm.o)))} -> #N/A
B7: KamUla | C7: ='grup-1'!H8 | D7: ='grup-1'!H39 | E7: ='grup-1'!H70 | F7: ='grup-1'!H101 | G7: ='grup-1'!H132 | H7: ='grup-1'!H163 | I7: ='grup-1'!H194 | J7: ='grup-1'!H225 | K7: ='grup-1'!H256 | L7: ='grup-1'!H287 | M7: ='grup-1'!H318 | N7: ='grup-1'!H349 | O7: ='grup-1'!H381 | P7: ='grup-1'!H412 | Q7: ='grup-1'!H443 | R7: ='grup-1'!H474 | S7: ='grup-1'!H505 | T7: ='grup-1'!H536 | U7: ='grup-1'!H567 | V7: ='grup-1'!H598 | W7: ='grup-1'!H629 | X7: ='grup-1'!H660 | Y7: ='grup-1'!H691 | Z7: ='grup-1'!H722 | AA7: =AB7*3+AC7*4+AD7*5 -> 0 | AB7: =COUNTIF(C7:Z7,3) -> 0 | AC7: =COUNTIF(C7:Z7,4) -> 0 | AD7: =COUNTIF(C7:Z7,5) -> 0 | AE7: {=_xlfn.LET(_xlpm.z,C7:Z7,_xlpm.o,MATCH(2,1/(_xlpm.z<>"")),_xlpm.p,MAX(1,_xlpm.o-4),SUM(INDEX(_xlpm.z,_xlpm.p):INDEX(_xlpm.z,_xlpm.o)))} -> #N/A
B8: MagdaS | C8: ='grup-1'!H9 | D8: ='grup-1'!H40 | E8: ='grup-1'!H71 | F8: ='grup-1'!H102 | G8: ='grup-1'!H133 | H8: ='grup-1'!H164 | I8: ='grup-1'!H195 | J8: ='grup-1'!H226 | K8: ='grup-1'!H257 | L8: ='grup-1'!H288 | M8: ='grup-1'!H319 | N8: ='grup-1'!H350 | O8: ='grup-1'!H382 | P8: ='grup-1'!H413 | Q8: ='grup-1'!H444 | R8: ='grup-1'!H475 | S8: ='grup-1'!H506 | T8: ='grup-1'!H537 | U8: ='grup-1'!H568 | V8: ='grup-1'!H599 | W8: ='grup-1'!H630 | X8: ='grup-1'!H661 | Y8: ='grup-1'!H692 | Z8: ='grup-1'!H723 | AA8: =AB8*3+AC8*4+AD8*5 -> 0 | AB8: =COUNTIF(C8:Z8,3) -> 0 | AC8: =COUNTIF(C8:Z8,4) -> 0 | AD8: =COUNTIF(C8:Z8,5) -> 0 | AE8: {=_xlfn.LET(_xlpm.z,C8:Z8,_xlpm.o,MATCH(2,1/(_xlpm.z<>"")),_xlpm.p,MAX(1,_xlpm.o-4),SUM(INDEX(_xlpm.z,_xlpm.p):INDEX(_xlpm.z,_xlpm.o)))} -> #N/A
B9: KasiaJ | C9: ='grup-1'!H10 | D9: ='grup-1'!H41 | E9: ='grup-1'!H72 | F9: ='grup-1'!H103 | G9: ='grup-1'!H134 | H9: ='grup-1'!H165 | I9: ='grup-1'!H196 | J9: ='grup-1'!H227 | K9: ='grup-1'!H258 | L9: ='grup-1'!H289 | M9: ='grup-1'!H320 | N9: ='grup-1'!H351 | O9: ='grup-1'!H383 | P9: ='grup-1'!H414 | Q9: ='grup-1'!H445 | R9: ='grup-1'!H476 | S9: ='grup-1'!H507 | T9: ='grup-1'!H538 | U9: ='grup-1'!H569 | V9: ='grup-1'!H600 | W9: ='grup-1'!H631 | X9: ='grup-1'!H662 | Y9: ='grup-1'!H693 | Z9: ='grup-1'!H724 | AA9: =AB9*3+AC9*4+AD9*5 -> 0 | AB9: =COUNTIF(C9:Z9,3) -> 0 | AC9: =COUNTIF(C9:Z9,4) -> 0 | AD9: =COUNTIF(C9:Z9,5) -> 0 | AE9: {=_xlfn.LET(_xlpm.z,C9:Z9,_xlpm.o,MATCH(2,1/(_xlpm.z<>"")),_xlpm.p,MAX(1,_xlpm.o-4),SUM(INDEX(_xlpm.z,_xlpm.p):INDEX(_xlpm.z,_xlpm.o)))} -> #N/A
B10: KrystianM | C10: ='grup-1'!H11 | D10: ='grup-1'!H42 | E10: ='grup-1'!H73 | F10: ='grup-1'!H104 | G10: ='grup-1'!H135 | H10: ='grup-1'!H166 | I10: ='grup-1'!H197 | J10: ='grup-1'!H228 | K10: ='grup-1'!H259 | L10: ='grup-1'!H290 | M10: ='grup-1'!H321 | N10: ='grup-1'!H352 | O10: ='grup-1'!H384 | P10: ='grup-1'!H415 | Q10: ='grup-1'!H446 | R10: ='grup-1'!H477 | S10: ='grup-1'!H508 | T10: ='grup-1'!H539 | U10: ='grup-1'!H570 | V10: ='grup-1'!H601 | W10: ='grup-1'!H632 | X10: ='grup-1'!H663 | Y10: ='grup-1'!H694 | Z10: ='grup-1'!H725 | AA10: =AB10*3+AC10*4+AD10*5 -> 0 | AB10: =COUNTIF(C10:Z10,3) -> 0 | AC10: =COUNTIF(C10:Z10,4) -> 0 | AD10: =COUNTIF(C10:Z10,5) -> 0 | AE10: {=_xlfn.LET(_xlpm.z,C10:Z10,_xlpm.o,MATCH(2,1/(_xlpm.z<>"")),_xlpm.p,MAX(1,_xlpm.o-4),SUM(INDEX(_xlpm.z,_xlpm.p):INDEX(_xlpm.z,_xlpm.o)))} -> #N/A
B11: PiotreG | C11: ='grup-1'!H12 | D11: ='grup-1'!H43 | E11: ='grup-1'!H74 | F11: ='grup-1'!H105 | G11: ='grup-1'!H136 | H11: ='grup-1'!H167 | I11: ='grup-1'!H198 | J11: ='grup-1'!H229 | K11: ='grup-1'!H260 | L11: ='grup-1'!H291 | M11: ='grup-1'!H322 | N11: ='grup-1'!H353 | O11: ='grup-1'!H385 | P11: ='grup-1'!H416 | Q11: ='grup-1'!H447 | R11: ='grup-1'!H478 | S11: ='grup-1'!H509 | T11: ='grup-1'!H540 | U11: ='grup-1'!H571 | V11: ='grup-1'!H602 | W11: ='grup-1'!H633 | X11: ='grup-1'!H664 | Y11: ='grup-1'!H695 | Z11: ='grup-1'!H726 | AA11: =AB11*3+AC11*4+AD11*5 -> 0 | AB11: =COUNTIF(C11:Z11,3) -> 0 | AC11: =COUNTIF(C11:Z11,4) -> 0 | AD11: =COUNTIF(C11:Z11,5) -> 0 | AE11: {=_xlfn.LET(_xlpm.z,C11:Z11,_xlpm.o,MATCH(2,1/(_xlpm.z<>"")),_xlpm.p,MAX(1,_xlpm.o-4),SUM(INDEX(_xlpm.z,_xlpm.p):INDEX(_xlpm.z,_xlpm.o)))} -> #N/A
B12: Prozped | C12: ='grup-1'!H13 | D12: ='grup-1'!H44 | E12: ='grup-1'!H75 | F12: ='grup-1'!H106 | G12: ='grup-1'!H137 | H12: ='grup-1'!H168 | I12: ='grup-1'!H199 | J12: ='grup-1'!H230 | K12: ='grup-1'!H261 | L12: ='grup-1'!H292 | M12: ='grup-1'!H323 | N12: ='grup-1'!H354 | O12: ='grup-1'!H386 | P12: ='grup-1'!H417 | Q12: ='grup-1'!H448 | R12: ='grup-1'!H479 | S12: ='grup-1'!H510 | T12: ='grup-1'!H541 | U12: ='grup-1'!H572 | V12: ='grup-1'!H603 | W12: ='grup-1'!H634 | X12: ='grup-1'!H665 | Y12: ='grup-1'!H696 | Z12: ='grup-1'!H727 | AA12: =AB12*3+AC12*4+AD12*5 -> 0 | AB12: =COUNTIF(C12:Z12,3) -> 0 | AC12: =COUNTIF(C12:Z12,4) -> 0 | AD12: =COUNTIF(C12:Z12,5) -> 0 | AE12: {=_xlfn.LET(_xlpm.z,C12:Z12,_xlpm.o,MATCH(2,1/(_xlpm.z<>"")),_xlpm.p,MAX(1,_xlpm.o-4),SUM(INDEX(_xlpm.z,_xlpm.p):INDEX(_xlpm.z,_xlpm.o)))} -> #N/A
B13: Artur | C13: ='grup-1'!H14 | D13: ='grup-1'!H45 | E13: ='grup-1'!H76 | F13: ='grup-1'!H107 | G13: ='grup-1'!H138 | H13: ='grup-1'!H169 | I13: ='grup-1'!H200 | J13: ='grup-1'!H231 | K13: ='grup-1'!H262 | L13: ='grup-1'!H293 | M13: ='grup-1'!H324 | N13: ='grup-1'!H355 | O13: ='grup-1'!H387 | P13: ='grup-1'!H418 | Q13: ='grup-1'!H449 | R13: ='grup-1'!H480 | S13: ='grup-1'!H511 | T13: ='grup-1'!H542 | U13: ='grup-1'!H573 | V13: ='grup-1'!H604 | W13: ='grup-1'!H635 | X13: ='grup-1'!H666 | Y13: ='grup-1'!H697 | Z13: ='grup-1'!H728 | AA13: =AB13*3+AC13*4+AD13*5 -> 0 | AB13: =COUNTIF(C13:Z13,3) -> 0 | AC13: =COUNTIF(C13:Z13,4) -> 0 | AD13: =COUNTIF(C13:Z13,5) -> 0 | AE13: {=_xlfn.LET(_xlpm.z,C13:Z13,_xlpm.o,MATCH(2,1/(_xlpm.z<>"")),_xlpm.p,MAX(1,_xlpm.o-4),SUM(INDEX(_xlpm.z,_xlpm.p):INDEX(_xlpm.z,_xlpm.o)))} -> #N/A
